self=$$;  ( mysqldump --single-transaction --quick --lock-tables=false -u _2056cbad3469cb38 -p********** _2056cbad3469cb38 -h 127.0.0.1 -P 3306   || kill $self )  | /usr/bin/gzip >> ./test.com/private/backups/20230805_000003-test_com-database.sql.gz

Backup Summary for test.com at 2023-08-05 00:00:04.174662
Config  : ./test.com/private/backups/20230805_000003-test_com-site_config_backup.json 116.0B
Database: ./test.com/private/backups/20230805_000003-test_com-database.sql.gz         270.5KiB
Backup for Site test.com has been successfully completed
self=$$;  ( mysqldump --single-transaction --quick --lock-tables=false -u _2056cbad3469cb38 -p********** _2056cbad3469cb38 -h 127.0.0.1 -P 3306   || kill $self )  | /usr/bin/gzip >> ./test.com/private/backups/20230805_120001-test_com-database.sql.gz

Backup Summary for test.com at 2023-08-05 12:00:01.646751
Config  : ./test.com/private/backups/20230805_120001-test_com-site_config_backup.json 116.0B
Database: ./test.com/private/backups/20230805_120001-test_com-database.sql.gz         278.5KiB
Backup for Site test.com has been successfully completed
self=$$;  ( mysqldump --single-transaction --quick --lock-tables=false -u _2056cbad3469cb38 -p********** _2056cbad3469cb38 -h 127.0.0.1 -P 3306   || kill $self )  | /usr/bin/gzip >> ./test.com/private/backups/20230806_180001-test_com-database.sql.gz

Backup Summary for test.com at 2023-08-06 18:00:02.000482
Config  : ./test.com/private/backups/20230806_180001-test_com-site_config_backup.json 116.0B
Database: ./test.com/private/backups/20230806_180001-test_com-database.sql.gz         1.1MiB
Backup for Site test.com has been successfully completed
self=$$;  ( mysqldump --single-transaction --quick --lock-tables=false -u _5a217055bf43ac19 -p********** _5a217055bf43ac19 -h 127.0.0.1 -P 3306   || kill $self )  | /usr/bin/gzip >> ./india.in/private/backups/20230808_120002-india_in-database.sql.gz

Backup Summary for india.in at 2023-08-08 12:00:02.680145
Config  : ./india.in/private/backups/20230808_120002-india_in-site_config_backup.json 94.0B
Database: ./india.in/private/backups/20230808_120002-india_in-database.sql.gz         1.1MiB
Backup for Site india.in has been successfully completed
Backup failed for Site library.test. Database or site_config.json may be corrupted
Traceback (most recent call last):
  File "apps/frappe/frappe/commands/site.py", line 718, in backup
    odb = scheduled_backup(
  File "apps/frappe/frappe/utils/backups.py", line 532, in scheduled_backup
    odb = new_backup(
  File "apps/frappe/frappe/utils/backups.py", line 566, in new_backup
    odb = BackupGenerator(
  File "apps/frappe/frappe/utils/backups.py", line 84, in __init__
    self.setup_backup_tables()
  File "apps/frappe/frappe/utils/backups.py", line 116, in setup_backup_tables
    existing_tables = frappe.db.get_tables()
  File "apps/frappe/frappe/database/mariadb/database.py", line 425, in get_tables
    frappe.qb.from_(information_schema.tables)
  File "apps/frappe/frappe/query_builder/utils.py", line 76, in execute_query
    return frappe.db.sql(query, params, *args, **kwargs)  # nosemgrep
  File "apps/frappe/frappe/database/database.py", line 201, in sql
    self.connect()
  File "apps/frappe/frappe/database/database.py", line 115, in connect
    self._conn = self.get_connection()
  File "apps/frappe/frappe/database/mariadb/database.py", line 98, in get_connection
    conn = self._get_connection()
  File "apps/frappe/frappe/database/mariadb/database.py", line 104, in _get_connection
    return self.create_connection()
  File "apps/frappe/frappe/database/mariadb/database.py", line 107, in create_connection
    return pymysql.connect(**self.get_connection_settings())
  File "env/lib/python3.10/site-packages/pymysql/connections.py", line 352, in __init__
    self.connect()
  File "env/lib/python3.10/site-packages/pymysql/connections.py", line 636, in connect
    self._request_authentication()
  File "env/lib/python3.10/site-packages/pymysql/connections.py", line 911, in _request_authentication
    auth_packet = self._read_packet()
  File "env/lib/python3.10/site-packages/pymysql/connections.py", line 729, in _read_packet
    packet.raise_for_error()
  File "env/lib/python3.10/site-packages/pymysql/protocol.py", line 221, in raise_for_error
    err.raise_mysql_exception(self._data)
  File "env/lib/python3.10/site-packages/pymysql/err.py", line 143, in raise_mysql_exception
    raise errorclass(errno, errval)
pymysql.err.OperationalError: (1045, "Access denied for user '_2117e1e8e8ec4e5b'@'localhost' (using password: YES)")

Backup failed for Site test.com. Database or site_config.json may be corrupted
Traceback (most recent call last):
  File "apps/frappe/frappe/commands/site.py", line 718, in backup
    odb = scheduled_backup(
  File "apps/frappe/frappe/utils/backups.py", line 532, in scheduled_backup
    odb = new_backup(
  File "apps/frappe/frappe/utils/backups.py", line 566, in new_backup
    odb = BackupGenerator(
  File "apps/frappe/frappe/utils/backups.py", line 84, in __init__
    self.setup_backup_tables()
  File "apps/frappe/frappe/utils/backups.py", line 116, in setup_backup_tables
    existing_tables = frappe.db.get_tables()
  File "apps/frappe/frappe/database/mariadb/database.py", line 425, in get_tables
    frappe.qb.from_(information_schema.tables)
  File "apps/frappe/frappe/query_builder/utils.py", line 76, in execute_query
    return frappe.db.sql(query, params, *args, **kwargs)  # nosemgrep
  File "apps/frappe/frappe/database/database.py", line 201, in sql
    self.connect()
  File "apps/frappe/frappe/database/database.py", line 115, in connect
    self._conn = self.get_connection()
  File "apps/frappe/frappe/database/mariadb/database.py", line 98, in get_connection
    conn = self._get_connection()
  File "apps/frappe/frappe/database/mariadb/database.py", line 104, in _get_connection
    return self.create_connection()
  File "apps/frappe/frappe/database/mariadb/database.py", line 107, in create_connection
    return pymysql.connect(**self.get_connection_settings())
  File "env/lib/python3.10/site-packages/pymysql/connections.py", line 352, in __init__
    self.connect()
  File "env/lib/python3.10/site-packages/pymysql/connections.py", line 636, in connect
    self._request_authentication()
  File "env/lib/python3.10/site-packages/pymysql/connections.py", line 911, in _request_authentication
    auth_packet = self._read_packet()
  File "env/lib/python3.10/site-packages/pymysql/connections.py", line 729, in _read_packet
    packet.raise_for_error()
  File "env/lib/python3.10/site-packages/pymysql/protocol.py", line 221, in raise_for_error
    err.raise_mysql_exception(self._data)
  File "env/lib/python3.10/site-packages/pymysql/err.py", line 143, in raise_mysql_exception
    raise errorclass(errno, errval)
pymysql.err.OperationalError: (1045, "Access denied for user '_2117e1e8e8ec4e5b'@'localhost' (using password: YES)")

Backup failed for Site test.in. Database or site_config.json may be corrupted
Traceback (most recent call last):
  File "apps/frappe/frappe/commands/site.py", line 718, in backup
    odb = scheduled_backup(
  File "apps/frappe/frappe/utils/backups.py", line 532, in scheduled_backup
    odb = new_backup(
  File "apps/frappe/frappe/utils/backups.py", line 566, in new_backup
    odb = BackupGenerator(
  File "apps/frappe/frappe/utils/backups.py", line 84, in __init__
    self.setup_backup_tables()
  File "apps/frappe/frappe/utils/backups.py", line 116, in setup_backup_tables
    existing_tables = frappe.db.get_tables()
  File "apps/frappe/frappe/database/mariadb/database.py", line 425, in get_tables
    frappe.qb.from_(information_schema.tables)
  File "apps/frappe/frappe/query_builder/utils.py", line 76, in execute_query
    return frappe.db.sql(query, params, *args, **kwargs)  # nosemgrep
  File "apps/frappe/frappe/database/database.py", line 201, in sql
    self.connect()
  File "apps/frappe/frappe/database/database.py", line 115, in connect
    self._conn = self.get_connection()
  File "apps/frappe/frappe/database/mariadb/database.py", line 98, in get_connection
    conn = self._get_connection()
  File "apps/frappe/frappe/database/mariadb/database.py", line 104, in _get_connection
    return self.create_connection()
  File "apps/frappe/frappe/database/mariadb/database.py", line 107, in create_connection
    return pymysql.connect(**self.get_connection_settings())
  File "env/lib/python3.10/site-packages/pymysql/connections.py", line 352, in __init__
    self.connect()
  File "env/lib/python3.10/site-packages/pymysql/connections.py", line 636, in connect
    self._request_authentication()
  File "env/lib/python3.10/site-packages/pymysql/connections.py", line 911, in _request_authentication
    auth_packet = self._read_packet()
  File "env/lib/python3.10/site-packages/pymysql/connections.py", line 729, in _read_packet
    packet.raise_for_error()
  File "env/lib/python3.10/site-packages/pymysql/protocol.py", line 221, in raise_for_error
    err.raise_mysql_exception(self._data)
  File "env/lib/python3.10/site-packages/pymysql/err.py", line 143, in raise_mysql_exception
    raise errorclass(errno, errval)
pymysql.err.OperationalError: (1045, "Access denied for user '_2117e1e8e8ec4e5b'@'localhost' (using password: YES)")

self=$$;  ( mysqldump --single-transaction --quick --lock-tables=false -u _5a217055bf43ac19 -p********** _5a217055bf43ac19 -h 127.0.0.1 -P 3306   || kill $self )  | /usr/bin/gzip >> ./india.in/private/backups/20230809_120001-india_in-database.sql.gz

Backup Summary for india.in at 2023-08-09 12:00:02.564974
Config  : ./india.in/private/backups/20230809_120001-india_in-site_config_backup.json 94.0B
Database: ./india.in/private/backups/20230809_120001-india_in-database.sql.gz         1.1MiB
Backup for Site india.in has been successfully completed
Backup failed for Site library.test. Database or site_config.json may be corrupted
Traceback (most recent call last):
  File "apps/frappe/frappe/commands/site.py", line 718, in backup
    odb = scheduled_backup(
  File "apps/frappe/frappe/utils/backups.py", line 532, in scheduled_backup
    odb = new_backup(
  File "apps/frappe/frappe/utils/backups.py", line 566, in new_backup
    odb = BackupGenerator(
  File "apps/frappe/frappe/utils/backups.py", line 84, in __init__
    self.setup_backup_tables()
  File "apps/frappe/frappe/utils/backups.py", line 116, in setup_backup_tables
    existing_tables = frappe.db.get_tables()
  File "apps/frappe/frappe/database/mariadb/database.py", line 425, in get_tables
    frappe.qb.from_(information_schema.tables)
  File "apps/frappe/frappe/query_builder/utils.py", line 76, in execute_query
    return frappe.db.sql(query, params, *args, **kwargs)  # nosemgrep
  File "apps/frappe/frappe/database/database.py", line 201, in sql
    self.connect()
  File "apps/frappe/frappe/database/database.py", line 115, in connect
    self._conn = self.get_connection()
  File "apps/frappe/frappe/database/mariadb/database.py", line 98, in get_connection
    conn = self._get_connection()
  File "apps/frappe/frappe/database/mariadb/database.py", line 104, in _get_connection
    return self.create_connection()
  File "apps/frappe/frappe/database/mariadb/database.py", line 107, in create_connection
    return pymysql.connect(**self.get_connection_settings())
  File "env/lib/python3.10/site-packages/pymysql/connections.py", line 352, in __init__
    self.connect()
  File "env/lib/python3.10/site-packages/pymysql/connections.py", line 636, in connect
    self._request_authentication()
  File "env/lib/python3.10/site-packages/pymysql/connections.py", line 911, in _request_authentication
    auth_packet = self._read_packet()
  File "env/lib/python3.10/site-packages/pymysql/connections.py", line 729, in _read_packet
    packet.raise_for_error()
  File "env/lib/python3.10/site-packages/pymysql/protocol.py", line 221, in raise_for_error
    err.raise_mysql_exception(self._data)
  File "env/lib/python3.10/site-packages/pymysql/err.py", line 143, in raise_mysql_exception
    raise errorclass(errno, errval)
pymysql.err.OperationalError: (1045, "Access denied for user '_2117e1e8e8ec4e5b'@'localhost' (using password: YES)")

Backup failed for Site test.com. Database or site_config.json may be corrupted
Traceback (most recent call last):
  File "apps/frappe/frappe/commands/site.py", line 718, in backup
    odb = scheduled_backup(
  File "apps/frappe/frappe/utils/backups.py", line 532, in scheduled_backup
    odb = new_backup(
  File "apps/frappe/frappe/utils/backups.py", line 566, in new_backup
    odb = BackupGenerator(
  File "apps/frappe/frappe/utils/backups.py", line 84, in __init__
    self.setup_backup_tables()
  File "apps/frappe/frappe/utils/backups.py", line 116, in setup_backup_tables
    existing_tables = frappe.db.get_tables()
  File "apps/frappe/frappe/database/mariadb/database.py", line 425, in get_tables
    frappe.qb.from_(information_schema.tables)
  File "apps/frappe/frappe/query_builder/utils.py", line 76, in execute_query
    return frappe.db.sql(query, params, *args, **kwargs)  # nosemgrep
  File "apps/frappe/frappe/database/database.py", line 201, in sql
    self.connect()
  File "apps/frappe/frappe/database/database.py", line 115, in connect
    self._conn = self.get_connection()
  File "apps/frappe/frappe/database/mariadb/database.py", line 98, in get_connection
    conn = self._get_connection()
  File "apps/frappe/frappe/database/mariadb/database.py", line 104, in _get_connection
    return self.create_connection()
  File "apps/frappe/frappe/database/mariadb/database.py", line 107, in create_connection
    return pymysql.connect(**self.get_connection_settings())
  File "env/lib/python3.10/site-packages/pymysql/connections.py", line 352, in __init__
    self.connect()
  File "env/lib/python3.10/site-packages/pymysql/connections.py", line 636, in connect
    self._request_authentication()
  File "env/lib/python3.10/site-packages/pymysql/connections.py", line 911, in _request_authentication
    auth_packet = self._read_packet()
  File "env/lib/python3.10/site-packages/pymysql/connections.py", line 729, in _read_packet
    packet.raise_for_error()
  File "env/lib/python3.10/site-packages/pymysql/protocol.py", line 221, in raise_for_error
    err.raise_mysql_exception(self._data)
  File "env/lib/python3.10/site-packages/pymysql/err.py", line 143, in raise_mysql_exception
    raise errorclass(errno, errval)
pymysql.err.OperationalError: (1045, "Access denied for user '_2117e1e8e8ec4e5b'@'localhost' (using password: YES)")

Backup failed for Site test.in. Database or site_config.json may be corrupted
Traceback (most recent call last):
  File "apps/frappe/frappe/commands/site.py", line 718, in backup
    odb = scheduled_backup(
  File "apps/frappe/frappe/utils/backups.py", line 532, in scheduled_backup
    odb = new_backup(
  File "apps/frappe/frappe/utils/backups.py", line 566, in new_backup
    odb = BackupGenerator(
  File "apps/frappe/frappe/utils/backups.py", line 84, in __init__
    self.setup_backup_tables()
  File "apps/frappe/frappe/utils/backups.py", line 116, in setup_backup_tables
    existing_tables = frappe.db.get_tables()
  File "apps/frappe/frappe/database/mariadb/database.py", line 425, in get_tables
    frappe.qb.from_(information_schema.tables)
  File "apps/frappe/frappe/query_builder/utils.py", line 76, in execute_query
    return frappe.db.sql(query, params, *args, **kwargs)  # nosemgrep
  File "apps/frappe/frappe/database/database.py", line 201, in sql
    self.connect()
  File "apps/frappe/frappe/database/database.py", line 115, in connect
    self._conn = self.get_connection()
  File "apps/frappe/frappe/database/mariadb/database.py", line 98, in get_connection
    conn = self._get_connection()
  File "apps/frappe/frappe/database/mariadb/database.py", line 104, in _get_connection
    return self.create_connection()
  File "apps/frappe/frappe/database/mariadb/database.py", line 107, in create_connection
    return pymysql.connect(**self.get_connection_settings())
  File "env/lib/python3.10/site-packages/pymysql/connections.py", line 352, in __init__
    self.connect()
  File "env/lib/python3.10/site-packages/pymysql/connections.py", line 636, in connect
    self._request_authentication()
  File "env/lib/python3.10/site-packages/pymysql/connections.py", line 911, in _request_authentication
    auth_packet = self._read_packet()
  File "env/lib/python3.10/site-packages/pymysql/connections.py", line 729, in _read_packet
    packet.raise_for_error()
  File "env/lib/python3.10/site-packages/pymysql/protocol.py", line 221, in raise_for_error
    err.raise_mysql_exception(self._data)
  File "env/lib/python3.10/site-packages/pymysql/err.py", line 143, in raise_mysql_exception
    raise errorclass(errno, errval)
pymysql.err.OperationalError: (1045, "Access denied for user '_2117e1e8e8ec4e5b'@'localhost' (using password: YES)")

self=$$;  ( mysqldump --single-transaction --quick --lock-tables=false -u _5a217055bf43ac19 -p********** _5a217055bf43ac19 -h 127.0.0.1 -P 3306   || kill $self )  | /usr/bin/gzip >> ./india.in/private/backups/20230810_120001-india_in-database.sql.gz

Backup Summary for india.in at 2023-08-10 12:00:02.524449
Config  : ./india.in/private/backups/20230810_120001-india_in-site_config_backup.json 94.0B
Database: ./india.in/private/backups/20230810_120001-india_in-database.sql.gz         1.1MiB
Backup for Site india.in has been successfully completed
Backup failed for Site library.test. Database or site_config.json may be corrupted
Traceback (most recent call last):
  File "apps/frappe/frappe/commands/site.py", line 718, in backup
    odb = scheduled_backup(
  File "apps/frappe/frappe/utils/backups.py", line 532, in scheduled_backup
    odb = new_backup(
  File "apps/frappe/frappe/utils/backups.py", line 566, in new_backup
    odb = BackupGenerator(
  File "apps/frappe/frappe/utils/backups.py", line 84, in __init__
    self.setup_backup_tables()
  File "apps/frappe/frappe/utils/backups.py", line 116, in setup_backup_tables
    existing_tables = frappe.db.get_tables()
  File "apps/frappe/frappe/database/mariadb/database.py", line 425, in get_tables
    frappe.qb.from_(information_schema.tables)
  File "apps/frappe/frappe/query_builder/utils.py", line 76, in execute_query
    return frappe.db.sql(query, params, *args, **kwargs)  # nosemgrep
  File "apps/frappe/frappe/database/database.py", line 201, in sql
    self.connect()
  File "apps/frappe/frappe/database/database.py", line 115, in connect
    self._conn = self.get_connection()
  File "apps/frappe/frappe/database/mariadb/database.py", line 98, in get_connection
    conn = self._get_connection()
  File "apps/frappe/frappe/database/mariadb/database.py", line 104, in _get_connection
    return self.create_connection()
  File "apps/frappe/frappe/database/mariadb/database.py", line 107, in create_connection
    return pymysql.connect(**self.get_connection_settings())
  File "env/lib/python3.10/site-packages/pymysql/connections.py", line 352, in __init__
    self.connect()
  File "env/lib/python3.10/site-packages/pymysql/connections.py", line 636, in connect
    self._request_authentication()
  File "env/lib/python3.10/site-packages/pymysql/connections.py", line 911, in _request_authentication
    auth_packet = self._read_packet()
  File "env/lib/python3.10/site-packages/pymysql/connections.py", line 729, in _read_packet
    packet.raise_for_error()
  File "env/lib/python3.10/site-packages/pymysql/protocol.py", line 221, in raise_for_error
    err.raise_mysql_exception(self._data)
  File "env/lib/python3.10/site-packages/pymysql/err.py", line 143, in raise_mysql_exception
    raise errorclass(errno, errval)
pymysql.err.OperationalError: (1045, "Access denied for user '_2117e1e8e8ec4e5b'@'localhost' (using password: YES)")

Backup failed for Site test.com. Database or site_config.json may be corrupted
Traceback (most recent call last):
  File "apps/frappe/frappe/commands/site.py", line 718, in backup
    odb = scheduled_backup(
  File "apps/frappe/frappe/utils/backups.py", line 532, in scheduled_backup
    odb = new_backup(
  File "apps/frappe/frappe/utils/backups.py", line 566, in new_backup
    odb = BackupGenerator(
  File "apps/frappe/frappe/utils/backups.py", line 84, in __init__
    self.setup_backup_tables()
  File "apps/frappe/frappe/utils/backups.py", line 116, in setup_backup_tables
    existing_tables = frappe.db.get_tables()
  File "apps/frappe/frappe/database/mariadb/database.py", line 425, in get_tables
    frappe.qb.from_(information_schema.tables)
  File "apps/frappe/frappe/query_builder/utils.py", line 76, in execute_query
    return frappe.db.sql(query, params, *args, **kwargs)  # nosemgrep
  File "apps/frappe/frappe/database/database.py", line 201, in sql
    self.connect()
  File "apps/frappe/frappe/database/database.py", line 115, in connect
    self._conn = self.get_connection()
  File "apps/frappe/frappe/database/mariadb/database.py", line 98, in get_connection
    conn = self._get_connection()
  File "apps/frappe/frappe/database/mariadb/database.py", line 104, in _get_connection
    return self.create_connection()
  File "apps/frappe/frappe/database/mariadb/database.py", line 107, in create_connection
    return pymysql.connect(**self.get_connection_settings())
  File "env/lib/python3.10/site-packages/pymysql/connections.py", line 352, in __init__
    self.connect()
  File "env/lib/python3.10/site-packages/pymysql/connections.py", line 636, in connect
    self._request_authentication()
  File "env/lib/python3.10/site-packages/pymysql/connections.py", line 911, in _request_authentication
    auth_packet = self._read_packet()
  File "env/lib/python3.10/site-packages/pymysql/connections.py", line 729, in _read_packet
    packet.raise_for_error()
  File "env/lib/python3.10/site-packages/pymysql/protocol.py", line 221, in raise_for_error
    err.raise_mysql_exception(self._data)
  File "env/lib/python3.10/site-packages/pymysql/err.py", line 143, in raise_mysql_exception
    raise errorclass(errno, errval)
pymysql.err.OperationalError: (1045, "Access denied for user '_2117e1e8e8ec4e5b'@'localhost' (using password: YES)")

Backup failed for Site test.in. Database or site_config.json may be corrupted
Traceback (most recent call last):
  File "apps/frappe/frappe/commands/site.py", line 718, in backup
    odb = scheduled_backup(
  File "apps/frappe/frappe/utils/backups.py", line 532, in scheduled_backup
    odb = new_backup(
  File "apps/frappe/frappe/utils/backups.py", line 566, in new_backup
    odb = BackupGenerator(
  File "apps/frappe/frappe/utils/backups.py", line 84, in __init__
    self.setup_backup_tables()
  File "apps/frappe/frappe/utils/backups.py", line 116, in setup_backup_tables
    existing_tables = frappe.db.get_tables()
  File "apps/frappe/frappe/database/mariadb/database.py", line 425, in get_tables
    frappe.qb.from_(information_schema.tables)
  File "apps/frappe/frappe/query_builder/utils.py", line 76, in execute_query
    return frappe.db.sql(query, params, *args, **kwargs)  # nosemgrep
  File "apps/frappe/frappe/database/database.py", line 201, in sql
    self.connect()
  File "apps/frappe/frappe/database/database.py", line 115, in connect
    self._conn = self.get_connection()
  File "apps/frappe/frappe/database/mariadb/database.py", line 98, in get_connection
    conn = self._get_connection()
  File "apps/frappe/frappe/database/mariadb/database.py", line 104, in _get_connection
    return self.create_connection()
  File "apps/frappe/frappe/database/mariadb/database.py", line 107, in create_connection
    return pymysql.connect(**self.get_connection_settings())
  File "env/lib/python3.10/site-packages/pymysql/connections.py", line 352, in __init__
    self.connect()
  File "env/lib/python3.10/site-packages/pymysql/connections.py", line 636, in connect
    self._request_authentication()
  File "env/lib/python3.10/site-packages/pymysql/connections.py", line 911, in _request_authentication
    auth_packet = self._read_packet()
  File "env/lib/python3.10/site-packages/pymysql/connections.py", line 729, in _read_packet
    packet.raise_for_error()
  File "env/lib/python3.10/site-packages/pymysql/protocol.py", line 221, in raise_for_error
    err.raise_mysql_exception(self._data)
  File "env/lib/python3.10/site-packages/pymysql/err.py", line 143, in raise_mysql_exception
    raise errorclass(errno, errval)
pymysql.err.OperationalError: (1045, "Access denied for user '_2117e1e8e8ec4e5b'@'localhost' (using password: YES)")

self=$$;  ( mysqldump --single-transaction --quick --lock-tables=false -u _5a217055bf43ac19 -p********** _5a217055bf43ac19 -h 127.0.0.1 -P 3306   || kill $self )  | /usr/bin/gzip >> ./india.in/private/backups/20230816_120001-india_in-database.sql.gz

Backup Summary for india.in at 2023-08-16 12:00:02.773897
Config  : ./india.in/private/backups/20230816_120001-india_in-site_config_backup.json 94.0B
Database: ./india.in/private/backups/20230816_120001-india_in-database.sql.gz         1.1MiB
Backup for Site india.in has been successfully completed
Backup failed for Site library.test. Database or site_config.json may be corrupted
Traceback (most recent call last):
  File "apps/frappe/frappe/commands/site.py", line 718, in backup
    odb = scheduled_backup(
  File "apps/frappe/frappe/utils/backups.py", line 532, in scheduled_backup
    odb = new_backup(
  File "apps/frappe/frappe/utils/backups.py", line 566, in new_backup
    odb = BackupGenerator(
  File "apps/frappe/frappe/utils/backups.py", line 84, in __init__
    self.setup_backup_tables()
  File "apps/frappe/frappe/utils/backups.py", line 116, in setup_backup_tables
    existing_tables = frappe.db.get_tables()
  File "apps/frappe/frappe/database/mariadb/database.py", line 425, in get_tables
    frappe.qb.from_(information_schema.tables)
  File "apps/frappe/frappe/query_builder/utils.py", line 76, in execute_query
    return frappe.db.sql(query, params, *args, **kwargs)  # nosemgrep
  File "apps/frappe/frappe/database/database.py", line 201, in sql
    self.connect()
  File "apps/frappe/frappe/database/database.py", line 115, in connect
    self._conn = self.get_connection()
  File "apps/frappe/frappe/database/mariadb/database.py", line 98, in get_connection
    conn = self._get_connection()
  File "apps/frappe/frappe/database/mariadb/database.py", line 104, in _get_connection
    return self.create_connection()
  File "apps/frappe/frappe/database/mariadb/database.py", line 107, in create_connection
    return pymysql.connect(**self.get_connection_settings())
  File "env/lib/python3.10/site-packages/pymysql/connections.py", line 352, in __init__
    self.connect()
  File "env/lib/python3.10/site-packages/pymysql/connections.py", line 636, in connect
    self._request_authentication()
  File "env/lib/python3.10/site-packages/pymysql/connections.py", line 911, in _request_authentication
    auth_packet = self._read_packet()
  File "env/lib/python3.10/site-packages/pymysql/connections.py", line 729, in _read_packet
    packet.raise_for_error()
  File "env/lib/python3.10/site-packages/pymysql/protocol.py", line 221, in raise_for_error
    err.raise_mysql_exception(self._data)
  File "env/lib/python3.10/site-packages/pymysql/err.py", line 143, in raise_mysql_exception
    raise errorclass(errno, errval)
pymysql.err.OperationalError: (1045, "Access denied for user '_2117e1e8e8ec4e5b'@'localhost' (using password: YES)")

Backup failed for Site test.com. Database or site_config.json may be corrupted
Traceback (most recent call last):
  File "apps/frappe/frappe/commands/site.py", line 718, in backup
    odb = scheduled_backup(
  File "apps/frappe/frappe/utils/backups.py", line 532, in scheduled_backup
    odb = new_backup(
  File "apps/frappe/frappe/utils/backups.py", line 566, in new_backup
    odb = BackupGenerator(
  File "apps/frappe/frappe/utils/backups.py", line 84, in __init__
    self.setup_backup_tables()
  File "apps/frappe/frappe/utils/backups.py", line 116, in setup_backup_tables
    existing_tables = frappe.db.get_tables()
  File "apps/frappe/frappe/database/mariadb/database.py", line 425, in get_tables
    frappe.qb.from_(information_schema.tables)
  File "apps/frappe/frappe/query_builder/utils.py", line 76, in execute_query
    return frappe.db.sql(query, params, *args, **kwargs)  # nosemgrep
  File "apps/frappe/frappe/database/database.py", line 201, in sql
    self.connect()
  File "apps/frappe/frappe/database/database.py", line 115, in connect
    self._conn = self.get_connection()
  File "apps/frappe/frappe/database/mariadb/database.py", line 98, in get_connection
    conn = self._get_connection()
  File "apps/frappe/frappe/database/mariadb/database.py", line 104, in _get_connection
    return self.create_connection()
  File "apps/frappe/frappe/database/mariadb/database.py", line 107, in create_connection
    return pymysql.connect(**self.get_connection_settings())
  File "env/lib/python3.10/site-packages/pymysql/connections.py", line 352, in __init__
    self.connect()
  File "env/lib/python3.10/site-packages/pymysql/connections.py", line 636, in connect
    self._request_authentication()
  File "env/lib/python3.10/site-packages/pymysql/connections.py", line 911, in _request_authentication
    auth_packet = self._read_packet()
  File "env/lib/python3.10/site-packages/pymysql/connections.py", line 729, in _read_packet
    packet.raise_for_error()
  File "env/lib/python3.10/site-packages/pymysql/protocol.py", line 221, in raise_for_error
    err.raise_mysql_exception(self._data)
  File "env/lib/python3.10/site-packages/pymysql/err.py", line 143, in raise_mysql_exception
    raise errorclass(errno, errval)
pymysql.err.OperationalError: (1045, "Access denied for user '_2117e1e8e8ec4e5b'@'localhost' (using password: YES)")

Backup failed for Site test.in. Database or site_config.json may be corrupted
Traceback (most recent call last):
  File "apps/frappe/frappe/commands/site.py", line 718, in backup
    odb = scheduled_backup(
  File "apps/frappe/frappe/utils/backups.py", line 532, in scheduled_backup
    odb = new_backup(
  File "apps/frappe/frappe/utils/backups.py", line 566, in new_backup
    odb = BackupGenerator(
  File "apps/frappe/frappe/utils/backups.py", line 84, in __init__
    self.setup_backup_tables()
  File "apps/frappe/frappe/utils/backups.py", line 116, in setup_backup_tables
    existing_tables = frappe.db.get_tables()
  File "apps/frappe/frappe/database/mariadb/database.py", line 425, in get_tables
    frappe.qb.from_(information_schema.tables)
  File "apps/frappe/frappe/query_builder/utils.py", line 76, in execute_query
    return frappe.db.sql(query, params, *args, **kwargs)  # nosemgrep
  File "apps/frappe/frappe/database/database.py", line 201, in sql
    self.connect()
  File "apps/frappe/frappe/database/database.py", line 115, in connect
    self._conn = self.get_connection()
  File "apps/frappe/frappe/database/mariadb/database.py", line 98, in get_connection
    conn = self._get_connection()
  File "apps/frappe/frappe/database/mariadb/database.py", line 104, in _get_connection
    return self.create_connection()
  File "apps/frappe/frappe/database/mariadb/database.py", line 107, in create_connection
    return pymysql.connect(**self.get_connection_settings())
  File "env/lib/python3.10/site-packages/pymysql/connections.py", line 352, in __init__
    self.connect()
  File "env/lib/python3.10/site-packages/pymysql/connections.py", line 636, in connect
    self._request_authentication()
  File "env/lib/python3.10/site-packages/pymysql/connections.py", line 911, in _request_authentication
    auth_packet = self._read_packet()
  File "env/lib/python3.10/site-packages/pymysql/connections.py", line 729, in _read_packet
    packet.raise_for_error()
  File "env/lib/python3.10/site-packages/pymysql/protocol.py", line 221, in raise_for_error
    err.raise_mysql_exception(self._data)
  File "env/lib/python3.10/site-packages/pymysql/err.py", line 143, in raise_mysql_exception
    raise errorclass(errno, errval)
pymysql.err.OperationalError: (1045, "Access denied for user '_2117e1e8e8ec4e5b'@'localhost' (using password: YES)")

self=$$;  ( mysqldump --single-transaction --quick --lock-tables=false -u _5a217055bf43ac19 -p********** _5a217055bf43ac19 -h 127.0.0.1 -P 3306   || kill $self )  | /usr/bin/gzip >> ./india.in/private/backups/20230818_120002-india_in-database.sql.gz

Backup Summary for india.in at 2023-08-18 12:00:03.424620
Config  : ./india.in/private/backups/20230818_120002-india_in-site_config_backup.json 94.0B
Database: ./india.in/private/backups/20230818_120002-india_in-database.sql.gz         1.1MiB
Backup for Site india.in has been successfully completed
Backup failed for Site library.test. Database or site_config.json may be corrupted
Traceback (most recent call last):
  File "apps/frappe/frappe/commands/site.py", line 718, in backup
    odb = scheduled_backup(
  File "apps/frappe/frappe/utils/backups.py", line 532, in scheduled_backup
    odb = new_backup(
  File "apps/frappe/frappe/utils/backups.py", line 566, in new_backup
    odb = BackupGenerator(
  File "apps/frappe/frappe/utils/backups.py", line 84, in __init__
    self.setup_backup_tables()
  File "apps/frappe/frappe/utils/backups.py", line 116, in setup_backup_tables
    existing_tables = frappe.db.get_tables()
  File "apps/frappe/frappe/database/mariadb/database.py", line 425, in get_tables
    frappe.qb.from_(information_schema.tables)
  File "apps/frappe/frappe/query_builder/utils.py", line 76, in execute_query
    return frappe.db.sql(query, params, *args, **kwargs)  # nosemgrep
  File "apps/frappe/frappe/database/database.py", line 201, in sql
    self.connect()
  File "apps/frappe/frappe/database/database.py", line 115, in connect
    self._conn = self.get_connection()
  File "apps/frappe/frappe/database/mariadb/database.py", line 98, in get_connection
    conn = self._get_connection()
  File "apps/frappe/frappe/database/mariadb/database.py", line 104, in _get_connection
    return self.create_connection()
  File "apps/frappe/frappe/database/mariadb/database.py", line 107, in create_connection
    return pymysql.connect(**self.get_connection_settings())
  File "env/lib/python3.10/site-packages/pymysql/connections.py", line 352, in __init__
    self.connect()
  File "env/lib/python3.10/site-packages/pymysql/connections.py", line 636, in connect
    self._request_authentication()
  File "env/lib/python3.10/site-packages/pymysql/connections.py", line 911, in _request_authentication
    auth_packet = self._read_packet()
  File "env/lib/python3.10/site-packages/pymysql/connections.py", line 729, in _read_packet
    packet.raise_for_error()
  File "env/lib/python3.10/site-packages/pymysql/protocol.py", line 221, in raise_for_error
    err.raise_mysql_exception(self._data)
  File "env/lib/python3.10/site-packages/pymysql/err.py", line 143, in raise_mysql_exception
    raise errorclass(errno, errval)
pymysql.err.OperationalError: (1045, "Access denied for user '_2117e1e8e8ec4e5b'@'localhost' (using password: YES)")

Backup failed for Site test.com. Database or site_config.json may be corrupted
Traceback (most recent call last):
  File "apps/frappe/frappe/commands/site.py", line 718, in backup
    odb = scheduled_backup(
  File "apps/frappe/frappe/utils/backups.py", line 532, in scheduled_backup
    odb = new_backup(
  File "apps/frappe/frappe/utils/backups.py", line 566, in new_backup
    odb = BackupGenerator(
  File "apps/frappe/frappe/utils/backups.py", line 84, in __init__
    self.setup_backup_tables()
  File "apps/frappe/frappe/utils/backups.py", line 116, in setup_backup_tables
    existing_tables = frappe.db.get_tables()
  File "apps/frappe/frappe/database/mariadb/database.py", line 425, in get_tables
    frappe.qb.from_(information_schema.tables)
  File "apps/frappe/frappe/query_builder/utils.py", line 76, in execute_query
    return frappe.db.sql(query, params, *args, **kwargs)  # nosemgrep
  File "apps/frappe/frappe/database/database.py", line 201, in sql
    self.connect()
  File "apps/frappe/frappe/database/database.py", line 115, in connect
    self._conn = self.get_connection()
  File "apps/frappe/frappe/database/mariadb/database.py", line 98, in get_connection
    conn = self._get_connection()
  File "apps/frappe/frappe/database/mariadb/database.py", line 104, in _get_connection
    return self.create_connection()
  File "apps/frappe/frappe/database/mariadb/database.py", line 107, in create_connection
    return pymysql.connect(**self.get_connection_settings())
  File "env/lib/python3.10/site-packages/pymysql/connections.py", line 352, in __init__
    self.connect()
  File "env/lib/python3.10/site-packages/pymysql/connections.py", line 636, in connect
    self._request_authentication()
  File "env/lib/python3.10/site-packages/pymysql/connections.py", line 911, in _request_authentication
    auth_packet = self._read_packet()
  File "env/lib/python3.10/site-packages/pymysql/connections.py", line 729, in _read_packet
    packet.raise_for_error()
  File "env/lib/python3.10/site-packages/pymysql/protocol.py", line 221, in raise_for_error
    err.raise_mysql_exception(self._data)
  File "env/lib/python3.10/site-packages/pymysql/err.py", line 143, in raise_mysql_exception
    raise errorclass(errno, errval)
pymysql.err.OperationalError: (1045, "Access denied for user '_2117e1e8e8ec4e5b'@'localhost' (using password: YES)")

Backup failed for Site test.in. Database or site_config.json may be corrupted
Traceback (most recent call last):
  File "apps/frappe/frappe/commands/site.py", line 718, in backup
    odb = scheduled_backup(
  File "apps/frappe/frappe/utils/backups.py", line 532, in scheduled_backup
    odb = new_backup(
  File "apps/frappe/frappe/utils/backups.py", line 566, in new_backup
    odb = BackupGenerator(
  File "apps/frappe/frappe/utils/backups.py", line 84, in __init__
    self.setup_backup_tables()
  File "apps/frappe/frappe/utils/backups.py", line 116, in setup_backup_tables
    existing_tables = frappe.db.get_tables()
  File "apps/frappe/frappe/database/mariadb/database.py", line 425, in get_tables
    frappe.qb.from_(information_schema.tables)
  File "apps/frappe/frappe/query_builder/utils.py", line 76, in execute_query
    return frappe.db.sql(query, params, *args, **kwargs)  # nosemgrep
  File "apps/frappe/frappe/database/database.py", line 201, in sql
    self.connect()
  File "apps/frappe/frappe/database/database.py", line 115, in connect
    self._conn = self.get_connection()
  File "apps/frappe/frappe/database/mariadb/database.py", line 98, in get_connection
    conn = self._get_connection()
  File "apps/frappe/frappe/database/mariadb/database.py", line 104, in _get_connection
    return self.create_connection()
  File "apps/frappe/frappe/database/mariadb/database.py", line 107, in create_connection
    return pymysql.connect(**self.get_connection_settings())
  File "env/lib/python3.10/site-packages/pymysql/connections.py", line 352, in __init__
    self.connect()
  File "env/lib/python3.10/site-packages/pymysql/connections.py", line 636, in connect
    self._request_authentication()
  File "env/lib/python3.10/site-packages/pymysql/connections.py", line 911, in _request_authentication
    auth_packet = self._read_packet()
  File "env/lib/python3.10/site-packages/pymysql/connections.py", line 729, in _read_packet
    packet.raise_for_error()
  File "env/lib/python3.10/site-packages/pymysql/protocol.py", line 221, in raise_for_error
    err.raise_mysql_exception(self._data)
  File "env/lib/python3.10/site-packages/pymysql/err.py", line 143, in raise_mysql_exception
    raise errorclass(errno, errval)
pymysql.err.OperationalError: (1045, "Access denied for user '_2117e1e8e8ec4e5b'@'localhost' (using password: YES)")

self=$$;  ( mysqldump --single-transaction --quick --lock-tables=false -u _5a217055bf43ac19 -p********** _5a217055bf43ac19 -h 127.0.0.1 -P 3306   || kill $self )  | /usr/bin/gzip >> ./india.in/private/backups/20230821_120002-india_in-database.sql.gz

Backup Summary for india.in at 2023-08-21 12:00:03.250310
Config  : ./india.in/private/backups/20230821_120002-india_in-site_config_backup.json 94.0B
Database: ./india.in/private/backups/20230821_120002-india_in-database.sql.gz         1.1MiB
Backup for Site india.in has been successfully completed
Backup failed for Site library.test. Database or site_config.json may be corrupted
Traceback (most recent call last):
  File "apps/frappe/frappe/commands/site.py", line 718, in backup
    odb = scheduled_backup(
  File "apps/frappe/frappe/utils/backups.py", line 532, in scheduled_backup
    odb = new_backup(
  File "apps/frappe/frappe/utils/backups.py", line 566, in new_backup
    odb = BackupGenerator(
  File "apps/frappe/frappe/utils/backups.py", line 84, in __init__
    self.setup_backup_tables()
  File "apps/frappe/frappe/utils/backups.py", line 116, in setup_backup_tables
    existing_tables = frappe.db.get_tables()
  File "apps/frappe/frappe/database/mariadb/database.py", line 425, in get_tables
    frappe.qb.from_(information_schema.tables)
  File "apps/frappe/frappe/query_builder/utils.py", line 76, in execute_query
    return frappe.db.sql(query, params, *args, **kwargs)  # nosemgrep
  File "apps/frappe/frappe/database/database.py", line 201, in sql
    self.connect()
  File "apps/frappe/frappe/database/database.py", line 115, in connect
    self._conn = self.get_connection()
  File "apps/frappe/frappe/database/mariadb/database.py", line 98, in get_connection
    conn = self._get_connection()
  File "apps/frappe/frappe/database/mariadb/database.py", line 104, in _get_connection
    return self.create_connection()
  File "apps/frappe/frappe/database/mariadb/database.py", line 107, in create_connection
    return pymysql.connect(**self.get_connection_settings())
  File "env/lib/python3.10/site-packages/pymysql/connections.py", line 352, in __init__
    self.connect()
  File "env/lib/python3.10/site-packages/pymysql/connections.py", line 636, in connect
    self._request_authentication()
  File "env/lib/python3.10/site-packages/pymysql/connections.py", line 911, in _request_authentication
    auth_packet = self._read_packet()
  File "env/lib/python3.10/site-packages/pymysql/connections.py", line 729, in _read_packet
    packet.raise_for_error()
  File "env/lib/python3.10/site-packages/pymysql/protocol.py", line 221, in raise_for_error
    err.raise_mysql_exception(self._data)
  File "env/lib/python3.10/site-packages/pymysql/err.py", line 143, in raise_mysql_exception
    raise errorclass(errno, errval)
pymysql.err.OperationalError: (1045, "Access denied for user '_2117e1e8e8ec4e5b'@'localhost' (using password: YES)")

Backup failed for Site test.com. Database or site_config.json may be corrupted
Traceback (most recent call last):
  File "apps/frappe/frappe/commands/site.py", line 718, in backup
    odb = scheduled_backup(
  File "apps/frappe/frappe/utils/backups.py", line 532, in scheduled_backup
    odb = new_backup(
  File "apps/frappe/frappe/utils/backups.py", line 566, in new_backup
    odb = BackupGenerator(
  File "apps/frappe/frappe/utils/backups.py", line 84, in __init__
    self.setup_backup_tables()
  File "apps/frappe/frappe/utils/backups.py", line 116, in setup_backup_tables
    existing_tables = frappe.db.get_tables()
  File "apps/frappe/frappe/database/mariadb/database.py", line 425, in get_tables
    frappe.qb.from_(information_schema.tables)
  File "apps/frappe/frappe/query_builder/utils.py", line 76, in execute_query
    return frappe.db.sql(query, params, *args, **kwargs)  # nosemgrep
  File "apps/frappe/frappe/database/database.py", line 201, in sql
    self.connect()
  File "apps/frappe/frappe/database/database.py", line 115, in connect
    self._conn = self.get_connection()
  File "apps/frappe/frappe/database/mariadb/database.py", line 98, in get_connection
    conn = self._get_connection()
  File "apps/frappe/frappe/database/mariadb/database.py", line 104, in _get_connection
    return self.create_connection()
  File "apps/frappe/frappe/database/mariadb/database.py", line 107, in create_connection
    return pymysql.connect(**self.get_connection_settings())
  File "env/lib/python3.10/site-packages/pymysql/connections.py", line 352, in __init__
    self.connect()
  File "env/lib/python3.10/site-packages/pymysql/connections.py", line 636, in connect
    self._request_authentication()
  File "env/lib/python3.10/site-packages/pymysql/connections.py", line 911, in _request_authentication
    auth_packet = self._read_packet()
  File "env/lib/python3.10/site-packages/pymysql/connections.py", line 729, in _read_packet
    packet.raise_for_error()
  File "env/lib/python3.10/site-packages/pymysql/protocol.py", line 221, in raise_for_error
    err.raise_mysql_exception(self._data)
  File "env/lib/python3.10/site-packages/pymysql/err.py", line 143, in raise_mysql_exception
    raise errorclass(errno, errval)
pymysql.err.OperationalError: (1045, "Access denied for user '_2117e1e8e8ec4e5b'@'localhost' (using password: YES)")

Backup failed for Site test.in. Database or site_config.json may be corrupted
Traceback (most recent call last):
  File "apps/frappe/frappe/commands/site.py", line 718, in backup
    odb = scheduled_backup(
  File "apps/frappe/frappe/utils/backups.py", line 532, in scheduled_backup
    odb = new_backup(
  File "apps/frappe/frappe/utils/backups.py", line 566, in new_backup
    odb = BackupGenerator(
  File "apps/frappe/frappe/utils/backups.py", line 84, in __init__
    self.setup_backup_tables()
  File "apps/frappe/frappe/utils/backups.py", line 116, in setup_backup_tables
    existing_tables = frappe.db.get_tables()
  File "apps/frappe/frappe/database/mariadb/database.py", line 425, in get_tables
    frappe.qb.from_(information_schema.tables)
  File "apps/frappe/frappe/query_builder/utils.py", line 76, in execute_query
    return frappe.db.sql(query, params, *args, **kwargs)  # nosemgrep
  File "apps/frappe/frappe/database/database.py", line 201, in sql
    self.connect()
  File "apps/frappe/frappe/database/database.py", line 115, in connect
    self._conn = self.get_connection()
  File "apps/frappe/frappe/database/mariadb/database.py", line 98, in get_connection
    conn = self._get_connection()
  File "apps/frappe/frappe/database/mariadb/database.py", line 104, in _get_connection
    return self.create_connection()
  File "apps/frappe/frappe/database/mariadb/database.py", line 107, in create_connection
    return pymysql.connect(**self.get_connection_settings())
  File "env/lib/python3.10/site-packages/pymysql/connections.py", line 352, in __init__
    self.connect()
  File "env/lib/python3.10/site-packages/pymysql/connections.py", line 636, in connect
    self._request_authentication()
  File "env/lib/python3.10/site-packages/pymysql/connections.py", line 911, in _request_authentication
    auth_packet = self._read_packet()
  File "env/lib/python3.10/site-packages/pymysql/connections.py", line 729, in _read_packet
    packet.raise_for_error()
  File "env/lib/python3.10/site-packages/pymysql/protocol.py", line 221, in raise_for_error
    err.raise_mysql_exception(self._data)
  File "env/lib/python3.10/site-packages/pymysql/err.py", line 143, in raise_mysql_exception
    raise errorclass(errno, errval)
pymysql.err.OperationalError: (1045, "Access denied for user '_2117e1e8e8ec4e5b'@'localhost' (using password: YES)")

self=$$;  ( mysqldump --single-transaction --quick --lock-tables=false -u _5a217055bf43ac19 -p********** _5a217055bf43ac19 -h 127.0.0.1 -P 3306   || kill $self )  | /usr/bin/gzip >> ./india.in/private/backups/20230822_120002-india_in-database.sql.gz

Backup Summary for india.in at 2023-08-22 12:00:03.092511
Config  : ./india.in/private/backups/20230822_120002-india_in-site_config_backup.json 94.0B
Database: ./india.in/private/backups/20230822_120002-india_in-database.sql.gz         1.1MiB
Backup for Site india.in has been successfully completed
Backup failed for Site library.test. Database or site_config.json may be corrupted
Traceback (most recent call last):
  File "apps/frappe/frappe/commands/site.py", line 718, in backup
    odb = scheduled_backup(
  File "apps/frappe/frappe/utils/backups.py", line 532, in scheduled_backup
    odb = new_backup(
  File "apps/frappe/frappe/utils/backups.py", line 566, in new_backup
    odb = BackupGenerator(
  File "apps/frappe/frappe/utils/backups.py", line 84, in __init__
    self.setup_backup_tables()
  File "apps/frappe/frappe/utils/backups.py", line 116, in setup_backup_tables
    existing_tables = frappe.db.get_tables()
  File "apps/frappe/frappe/database/mariadb/database.py", line 425, in get_tables
    frappe.qb.from_(information_schema.tables)
  File "apps/frappe/frappe/query_builder/utils.py", line 76, in execute_query
    return frappe.db.sql(query, params, *args, **kwargs)  # nosemgrep
  File "apps/frappe/frappe/database/database.py", line 201, in sql
    self.connect()
  File "apps/frappe/frappe/database/database.py", line 115, in connect
    self._conn = self.get_connection()
  File "apps/frappe/frappe/database/mariadb/database.py", line 98, in get_connection
    conn = self._get_connection()
  File "apps/frappe/frappe/database/mariadb/database.py", line 104, in _get_connection
    return self.create_connection()
  File "apps/frappe/frappe/database/mariadb/database.py", line 107, in create_connection
    return pymysql.connect(**self.get_connection_settings())
  File "env/lib/python3.10/site-packages/pymysql/connections.py", line 352, in __init__
    self.connect()
  File "env/lib/python3.10/site-packages/pymysql/connections.py", line 636, in connect
    self._request_authentication()
  File "env/lib/python3.10/site-packages/pymysql/connections.py", line 911, in _request_authentication
    auth_packet = self._read_packet()
  File "env/lib/python3.10/site-packages/pymysql/connections.py", line 729, in _read_packet
    packet.raise_for_error()
  File "env/lib/python3.10/site-packages/pymysql/protocol.py", line 221, in raise_for_error
    err.raise_mysql_exception(self._data)
  File "env/lib/python3.10/site-packages/pymysql/err.py", line 143, in raise_mysql_exception
    raise errorclass(errno, errval)
pymysql.err.OperationalError: (1045, "Access denied for user '_2117e1e8e8ec4e5b'@'localhost' (using password: YES)")

Backup failed for Site test.com. Database or site_config.json may be corrupted
Traceback (most recent call last):
  File "apps/frappe/frappe/commands/site.py", line 718, in backup
    odb = scheduled_backup(
  File "apps/frappe/frappe/utils/backups.py", line 532, in scheduled_backup
    odb = new_backup(
  File "apps/frappe/frappe/utils/backups.py", line 566, in new_backup
    odb = BackupGenerator(
  File "apps/frappe/frappe/utils/backups.py", line 84, in __init__
    self.setup_backup_tables()
  File "apps/frappe/frappe/utils/backups.py", line 116, in setup_backup_tables
    existing_tables = frappe.db.get_tables()
  File "apps/frappe/frappe/database/mariadb/database.py", line 425, in get_tables
    frappe.qb.from_(information_schema.tables)
  File "apps/frappe/frappe/query_builder/utils.py", line 76, in execute_query
    return frappe.db.sql(query, params, *args, **kwargs)  # nosemgrep
  File "apps/frappe/frappe/database/database.py", line 201, in sql
    self.connect()
  File "apps/frappe/frappe/database/database.py", line 115, in connect
    self._conn = self.get_connection()
  File "apps/frappe/frappe/database/mariadb/database.py", line 98, in get_connection
    conn = self._get_connection()
  File "apps/frappe/frappe/database/mariadb/database.py", line 104, in _get_connection
    return self.create_connection()
  File "apps/frappe/frappe/database/mariadb/database.py", line 107, in create_connection
    return pymysql.connect(**self.get_connection_settings())
  File "env/lib/python3.10/site-packages/pymysql/connections.py", line 352, in __init__
    self.connect()
  File "env/lib/python3.10/site-packages/pymysql/connections.py", line 636, in connect
    self._request_authentication()
  File "env/lib/python3.10/site-packages/pymysql/connections.py", line 911, in _request_authentication
    auth_packet = self._read_packet()
  File "env/lib/python3.10/site-packages/pymysql/connections.py", line 729, in _read_packet
    packet.raise_for_error()
  File "env/lib/python3.10/site-packages/pymysql/protocol.py", line 221, in raise_for_error
    err.raise_mysql_exception(self._data)
  File "env/lib/python3.10/site-packages/pymysql/err.py", line 143, in raise_mysql_exception
    raise errorclass(errno, errval)
pymysql.err.OperationalError: (1045, "Access denied for user '_2117e1e8e8ec4e5b'@'localhost' (using password: YES)")

Backup failed for Site test.in. Database or site_config.json may be corrupted
Traceback (most recent call last):
  File "apps/frappe/frappe/commands/site.py", line 718, in backup
    odb = scheduled_backup(
  File "apps/frappe/frappe/utils/backups.py", line 532, in scheduled_backup
    odb = new_backup(
  File "apps/frappe/frappe/utils/backups.py", line 566, in new_backup
    odb = BackupGenerator(
  File "apps/frappe/frappe/utils/backups.py", line 84, in __init__
    self.setup_backup_tables()
  File "apps/frappe/frappe/utils/backups.py", line 116, in setup_backup_tables
    existing_tables = frappe.db.get_tables()
  File "apps/frappe/frappe/database/mariadb/database.py", line 425, in get_tables
    frappe.qb.from_(information_schema.tables)
  File "apps/frappe/frappe/query_builder/utils.py", line 76, in execute_query
    return frappe.db.sql(query, params, *args, **kwargs)  # nosemgrep
  File "apps/frappe/frappe/database/database.py", line 201, in sql
    self.connect()
  File "apps/frappe/frappe/database/database.py", line 115, in connect
    self._conn = self.get_connection()
  File "apps/frappe/frappe/database/mariadb/database.py", line 98, in get_connection
    conn = self._get_connection()
  File "apps/frappe/frappe/database/mariadb/database.py", line 104, in _get_connection
    return self.create_connection()
  File "apps/frappe/frappe/database/mariadb/database.py", line 107, in create_connection
    return pymysql.connect(**self.get_connection_settings())
  File "env/lib/python3.10/site-packages/pymysql/connections.py", line 352, in __init__
    self.connect()
  File "env/lib/python3.10/site-packages/pymysql/connections.py", line 636, in connect
    self._request_authentication()
  File "env/lib/python3.10/site-packages/pymysql/connections.py", line 911, in _request_authentication
    auth_packet = self._read_packet()
  File "env/lib/python3.10/site-packages/pymysql/connections.py", line 729, in _read_packet
    packet.raise_for_error()
  File "env/lib/python3.10/site-packages/pymysql/protocol.py", line 221, in raise_for_error
    err.raise_mysql_exception(self._data)
  File "env/lib/python3.10/site-packages/pymysql/err.py", line 143, in raise_mysql_exception
    raise errorclass(errno, errval)
pymysql.err.OperationalError: (1045, "Access denied for user '_2117e1e8e8ec4e5b'@'localhost' (using password: YES)")

self=$$;  ( mysqldump --single-transaction --quick --lock-tables=false -u _5a217055bf43ac19 -p********** _5a217055bf43ac19 -h 127.0.0.1 -P 3306   || kill $self )  | /usr/bin/gzip >> ./india.in/private/backups/20230824_120002-india_in-database.sql.gz

Backup Summary for india.in at 2023-08-24 12:00:03.303189
Config  : ./india.in/private/backups/20230824_120002-india_in-site_config_backup.json 94.0B
Database: ./india.in/private/backups/20230824_120002-india_in-database.sql.gz         1.1MiB
Backup for Site india.in has been successfully completed
Backup failed for Site library.test. Database or site_config.json may be corrupted
Traceback (most recent call last):
  File "apps/frappe/frappe/commands/site.py", line 718, in backup
    odb = scheduled_backup(
  File "apps/frappe/frappe/utils/backups.py", line 532, in scheduled_backup
    odb = new_backup(
  File "apps/frappe/frappe/utils/backups.py", line 566, in new_backup
    odb = BackupGenerator(
  File "apps/frappe/frappe/utils/backups.py", line 84, in __init__
    self.setup_backup_tables()
  File "apps/frappe/frappe/utils/backups.py", line 116, in setup_backup_tables
    existing_tables = frappe.db.get_tables()
  File "apps/frappe/frappe/database/mariadb/database.py", line 425, in get_tables
    frappe.qb.from_(information_schema.tables)
  File "apps/frappe/frappe/query_builder/utils.py", line 76, in execute_query
    return frappe.db.sql(query, params, *args, **kwargs)  # nosemgrep
  File "apps/frappe/frappe/database/database.py", line 201, in sql
    self.connect()
  File "apps/frappe/frappe/database/database.py", line 115, in connect
    self._conn = self.get_connection()
  File "apps/frappe/frappe/database/mariadb/database.py", line 98, in get_connection
    conn = self._get_connection()
  File "apps/frappe/frappe/database/mariadb/database.py", line 104, in _get_connection
    return self.create_connection()
  File "apps/frappe/frappe/database/mariadb/database.py", line 107, in create_connection
    return pymysql.connect(**self.get_connection_settings())
  File "env/lib/python3.10/site-packages/pymysql/connections.py", line 352, in __init__
    self.connect()
  File "env/lib/python3.10/site-packages/pymysql/connections.py", line 636, in connect
    self._request_authentication()
  File "env/lib/python3.10/site-packages/pymysql/connections.py", line 911, in _request_authentication
    auth_packet = self._read_packet()
  File "env/lib/python3.10/site-packages/pymysql/connections.py", line 729, in _read_packet
    packet.raise_for_error()
  File "env/lib/python3.10/site-packages/pymysql/protocol.py", line 221, in raise_for_error
    err.raise_mysql_exception(self._data)
  File "env/lib/python3.10/site-packages/pymysql/err.py", line 143, in raise_mysql_exception
    raise errorclass(errno, errval)
pymysql.err.OperationalError: (1045, "Access denied for user '_2117e1e8e8ec4e5b'@'localhost' (using password: YES)")

Backup failed for Site test.com. Database or site_config.json may be corrupted
Traceback (most recent call last):
  File "apps/frappe/frappe/commands/site.py", line 718, in backup
    odb = scheduled_backup(
  File "apps/frappe/frappe/utils/backups.py", line 532, in scheduled_backup
    odb = new_backup(
  File "apps/frappe/frappe/utils/backups.py", line 566, in new_backup
    odb = BackupGenerator(
  File "apps/frappe/frappe/utils/backups.py", line 84, in __init__
    self.setup_backup_tables()
  File "apps/frappe/frappe/utils/backups.py", line 116, in setup_backup_tables
    existing_tables = frappe.db.get_tables()
  File "apps/frappe/frappe/database/mariadb/database.py", line 425, in get_tables
    frappe.qb.from_(information_schema.tables)
  File "apps/frappe/frappe/query_builder/utils.py", line 76, in execute_query
    return frappe.db.sql(query, params, *args, **kwargs)  # nosemgrep
  File "apps/frappe/frappe/database/database.py", line 201, in sql
    self.connect()
  File "apps/frappe/frappe/database/database.py", line 115, in connect
    self._conn = self.get_connection()
  File "apps/frappe/frappe/database/mariadb/database.py", line 98, in get_connection
    conn = self._get_connection()
  File "apps/frappe/frappe/database/mariadb/database.py", line 104, in _get_connection
    return self.create_connection()
  File "apps/frappe/frappe/database/mariadb/database.py", line 107, in create_connection
    return pymysql.connect(**self.get_connection_settings())
  File "env/lib/python3.10/site-packages/pymysql/connections.py", line 352, in __init__
    self.connect()
  File "env/lib/python3.10/site-packages/pymysql/connections.py", line 636, in connect
    self._request_authentication()
  File "env/lib/python3.10/site-packages/pymysql/connections.py", line 911, in _request_authentication
    auth_packet = self._read_packet()
  File "env/lib/python3.10/site-packages/pymysql/connections.py", line 729, in _read_packet
    packet.raise_for_error()
  File "env/lib/python3.10/site-packages/pymysql/protocol.py", line 221, in raise_for_error
    err.raise_mysql_exception(self._data)
  File "env/lib/python3.10/site-packages/pymysql/err.py", line 143, in raise_mysql_exception
    raise errorclass(errno, errval)
pymysql.err.OperationalError: (1045, "Access denied for user '_2117e1e8e8ec4e5b'@'localhost' (using password: YES)")

Backup failed for Site test.in. Database or site_config.json may be corrupted
Traceback (most recent call last):
  File "apps/frappe/frappe/commands/site.py", line 718, in backup
    odb = scheduled_backup(
  File "apps/frappe/frappe/utils/backups.py", line 532, in scheduled_backup
    odb = new_backup(
  File "apps/frappe/frappe/utils/backups.py", line 566, in new_backup
    odb = BackupGenerator(
  File "apps/frappe/frappe/utils/backups.py", line 84, in __init__
    self.setup_backup_tables()
  File "apps/frappe/frappe/utils/backups.py", line 116, in setup_backup_tables
    existing_tables = frappe.db.get_tables()
  File "apps/frappe/frappe/database/mariadb/database.py", line 425, in get_tables
    frappe.qb.from_(information_schema.tables)
  File "apps/frappe/frappe/query_builder/utils.py", line 76, in execute_query
    return frappe.db.sql(query, params, *args, **kwargs)  # nosemgrep
  File "apps/frappe/frappe/database/database.py", line 201, in sql
    self.connect()
  File "apps/frappe/frappe/database/database.py", line 115, in connect
    self._conn = self.get_connection()
  File "apps/frappe/frappe/database/mariadb/database.py", line 98, in get_connection
    conn = self._get_connection()
  File "apps/frappe/frappe/database/mariadb/database.py", line 104, in _get_connection
    return self.create_connection()
  File "apps/frappe/frappe/database/mariadb/database.py", line 107, in create_connection
    return pymysql.connect(**self.get_connection_settings())
  File "env/lib/python3.10/site-packages/pymysql/connections.py", line 352, in __init__
    self.connect()
  File "env/lib/python3.10/site-packages/pymysql/connections.py", line 636, in connect
    self._request_authentication()
  File "env/lib/python3.10/site-packages/pymysql/connections.py", line 911, in _request_authentication
    auth_packet = self._read_packet()
  File "env/lib/python3.10/site-packages/pymysql/connections.py", line 729, in _read_packet
    packet.raise_for_error()
  File "env/lib/python3.10/site-packages/pymysql/protocol.py", line 221, in raise_for_error
    err.raise_mysql_exception(self._data)
  File "env/lib/python3.10/site-packages/pymysql/err.py", line 143, in raise_mysql_exception
    raise errorclass(errno, errval)
pymysql.err.OperationalError: (1045, "Access denied for user '_2117e1e8e8ec4e5b'@'localhost' (using password: YES)")

self=$$;  ( mysqldump --single-transaction --quick --lock-tables=false -u _5a217055bf43ac19 -p********** _5a217055bf43ac19 -h 127.0.0.1 -P 3306   || kill $self )  | /usr/bin/gzip >> ./india.in/private/backups/20230828_120001-india_in-database.sql.gz

Backup Summary for india.in at 2023-08-28 12:00:02.911124
Config  : ./india.in/private/backups/20230828_120001-india_in-site_config_backup.json 94.0B
Database: ./india.in/private/backups/20230828_120001-india_in-database.sql.gz         1.1MiB
Backup for Site india.in has been successfully completed
Backup failed for Site library.test. Database or site_config.json may be corrupted
Traceback (most recent call last):
  File "apps/frappe/frappe/commands/site.py", line 718, in backup
    odb = scheduled_backup(
  File "apps/frappe/frappe/utils/backups.py", line 532, in scheduled_backup
    odb = new_backup(
  File "apps/frappe/frappe/utils/backups.py", line 566, in new_backup
    odb = BackupGenerator(
  File "apps/frappe/frappe/utils/backups.py", line 84, in __init__
    self.setup_backup_tables()
  File "apps/frappe/frappe/utils/backups.py", line 116, in setup_backup_tables
    existing_tables = frappe.db.get_tables()
  File "apps/frappe/frappe/database/mariadb/database.py", line 425, in get_tables
    frappe.qb.from_(information_schema.tables)
  File "apps/frappe/frappe/query_builder/utils.py", line 76, in execute_query
    return frappe.db.sql(query, params, *args, **kwargs)  # nosemgrep
  File "apps/frappe/frappe/database/database.py", line 201, in sql
    self.connect()
  File "apps/frappe/frappe/database/database.py", line 115, in connect
    self._conn = self.get_connection()
  File "apps/frappe/frappe/database/mariadb/database.py", line 98, in get_connection
    conn = self._get_connection()
  File "apps/frappe/frappe/database/mariadb/database.py", line 104, in _get_connection
    return self.create_connection()
  File "apps/frappe/frappe/database/mariadb/database.py", line 107, in create_connection
    return pymysql.connect(**self.get_connection_settings())
  File "env/lib/python3.10/site-packages/pymysql/connections.py", line 352, in __init__
    self.connect()
  File "env/lib/python3.10/site-packages/pymysql/connections.py", line 636, in connect
    self._request_authentication()
  File "env/lib/python3.10/site-packages/pymysql/connections.py", line 911, in _request_authentication
    auth_packet = self._read_packet()
  File "env/lib/python3.10/site-packages/pymysql/connections.py", line 729, in _read_packet
    packet.raise_for_error()
  File "env/lib/python3.10/site-packages/pymysql/protocol.py", line 221, in raise_for_error
    err.raise_mysql_exception(self._data)
  File "env/lib/python3.10/site-packages/pymysql/err.py", line 143, in raise_mysql_exception
    raise errorclass(errno, errval)
pymysql.err.OperationalError: (1045, "Access denied for user '_2117e1e8e8ec4e5b'@'localhost' (using password: YES)")

Backup failed for Site test.com. Database or site_config.json may be corrupted
Traceback (most recent call last):
  File "apps/frappe/frappe/commands/site.py", line 718, in backup
    odb = scheduled_backup(
  File "apps/frappe/frappe/utils/backups.py", line 532, in scheduled_backup
    odb = new_backup(
  File "apps/frappe/frappe/utils/backups.py", line 566, in new_backup
    odb = BackupGenerator(
  File "apps/frappe/frappe/utils/backups.py", line 84, in __init__
    self.setup_backup_tables()
  File "apps/frappe/frappe/utils/backups.py", line 116, in setup_backup_tables
    existing_tables = frappe.db.get_tables()
  File "apps/frappe/frappe/database/mariadb/database.py", line 425, in get_tables
    frappe.qb.from_(information_schema.tables)
  File "apps/frappe/frappe/query_builder/utils.py", line 76, in execute_query
    return frappe.db.sql(query, params, *args, **kwargs)  # nosemgrep
  File "apps/frappe/frappe/database/database.py", line 201, in sql
    self.connect()
  File "apps/frappe/frappe/database/database.py", line 115, in connect
    self._conn = self.get_connection()
  File "apps/frappe/frappe/database/mariadb/database.py", line 98, in get_connection
    conn = self._get_connection()
  File "apps/frappe/frappe/database/mariadb/database.py", line 104, in _get_connection
    return self.create_connection()
  File "apps/frappe/frappe/database/mariadb/database.py", line 107, in create_connection
    return pymysql.connect(**self.get_connection_settings())
  File "env/lib/python3.10/site-packages/pymysql/connections.py", line 352, in __init__
    self.connect()
  File "env/lib/python3.10/site-packages/pymysql/connections.py", line 636, in connect
    self._request_authentication()
  File "env/lib/python3.10/site-packages/pymysql/connections.py", line 911, in _request_authentication
    auth_packet = self._read_packet()
  File "env/lib/python3.10/site-packages/pymysql/connections.py", line 729, in _read_packet
    packet.raise_for_error()
  File "env/lib/python3.10/site-packages/pymysql/protocol.py", line 221, in raise_for_error
    err.raise_mysql_exception(self._data)
  File "env/lib/python3.10/site-packages/pymysql/err.py", line 143, in raise_mysql_exception
    raise errorclass(errno, errval)
pymysql.err.OperationalError: (1045, "Access denied for user '_2117e1e8e8ec4e5b'@'localhost' (using password: YES)")

Backup failed for Site test.in. Database or site_config.json may be corrupted
Traceback (most recent call last):
  File "apps/frappe/frappe/commands/site.py", line 718, in backup
    odb = scheduled_backup(
  File "apps/frappe/frappe/utils/backups.py", line 532, in scheduled_backup
    odb = new_backup(
  File "apps/frappe/frappe/utils/backups.py", line 566, in new_backup
    odb = BackupGenerator(
  File "apps/frappe/frappe/utils/backups.py", line 84, in __init__
    self.setup_backup_tables()
  File "apps/frappe/frappe/utils/backups.py", line 116, in setup_backup_tables
    existing_tables = frappe.db.get_tables()
  File "apps/frappe/frappe/database/mariadb/database.py", line 425, in get_tables
    frappe.qb.from_(information_schema.tables)
  File "apps/frappe/frappe/query_builder/utils.py", line 76, in execute_query
    return frappe.db.sql(query, params, *args, **kwargs)  # nosemgrep
  File "apps/frappe/frappe/database/database.py", line 201, in sql
    self.connect()
  File "apps/frappe/frappe/database/database.py", line 115, in connect
    self._conn = self.get_connection()
  File "apps/frappe/frappe/database/mariadb/database.py", line 98, in get_connection
    conn = self._get_connection()
  File "apps/frappe/frappe/database/mariadb/database.py", line 104, in _get_connection
    return self.create_connection()
  File "apps/frappe/frappe/database/mariadb/database.py", line 107, in create_connection
    return pymysql.connect(**self.get_connection_settings())
  File "env/lib/python3.10/site-packages/pymysql/connections.py", line 352, in __init__
    self.connect()
  File "env/lib/python3.10/site-packages/pymysql/connections.py", line 636, in connect
    self._request_authentication()
  File "env/lib/python3.10/site-packages/pymysql/connections.py", line 911, in _request_authentication
    auth_packet = self._read_packet()
  File "env/lib/python3.10/site-packages/pymysql/connections.py", line 729, in _read_packet
    packet.raise_for_error()
  File "env/lib/python3.10/site-packages/pymysql/protocol.py", line 221, in raise_for_error
    err.raise_mysql_exception(self._data)
  File "env/lib/python3.10/site-packages/pymysql/err.py", line 143, in raise_mysql_exception
    raise errorclass(errno, errval)
pymysql.err.OperationalError: (1045, "Access denied for user '_2117e1e8e8ec4e5b'@'localhost' (using password: YES)")

self=$$;  ( mysqldump --single-transaction --quick --lock-tables=false -u _5a217055bf43ac19 -p********** _5a217055bf43ac19 -h 127.0.0.1 -P 3306   || kill $self )  | /usr/bin/gzip >> ./india.in/private/backups/20230902_180001-india_in-database.sql.gz

Backup Summary for india.in at 2023-09-02 18:00:03.102162
Config  : ./india.in/private/backups/20230902_180001-india_in-site_config_backup.json 94.0B
Database: ./india.in/private/backups/20230902_180001-india_in-database.sql.gz         1.1MiB
Backup for Site india.in has been successfully completed
Backup failed for Site library.test. Database or site_config.json may be corrupted
Traceback (most recent call last):
  File "apps/frappe/frappe/commands/site.py", line 718, in backup
    odb = scheduled_backup(
  File "apps/frappe/frappe/utils/backups.py", line 532, in scheduled_backup
    odb = new_backup(
  File "apps/frappe/frappe/utils/backups.py", line 566, in new_backup
    odb = BackupGenerator(
  File "apps/frappe/frappe/utils/backups.py", line 84, in __init__
    self.setup_backup_tables()
  File "apps/frappe/frappe/utils/backups.py", line 116, in setup_backup_tables
    existing_tables = frappe.db.get_tables()
  File "apps/frappe/frappe/database/mariadb/database.py", line 425, in get_tables
    frappe.qb.from_(information_schema.tables)
  File "apps/frappe/frappe/query_builder/utils.py", line 76, in execute_query
    return frappe.db.sql(query, params, *args, **kwargs)  # nosemgrep
  File "apps/frappe/frappe/database/database.py", line 201, in sql
    self.connect()
  File "apps/frappe/frappe/database/database.py", line 115, in connect
    self._conn = self.get_connection()
  File "apps/frappe/frappe/database/mariadb/database.py", line 98, in get_connection
    conn = self._get_connection()
  File "apps/frappe/frappe/database/mariadb/database.py", line 104, in _get_connection
    return self.create_connection()
  File "apps/frappe/frappe/database/mariadb/database.py", line 107, in create_connection
    return pymysql.connect(**self.get_connection_settings())
  File "env/lib/python3.10/site-packages/pymysql/connections.py", line 352, in __init__
    self.connect()
  File "env/lib/python3.10/site-packages/pymysql/connections.py", line 636, in connect
    self._request_authentication()
  File "env/lib/python3.10/site-packages/pymysql/connections.py", line 911, in _request_authentication
    auth_packet = self._read_packet()
  File "env/lib/python3.10/site-packages/pymysql/connections.py", line 729, in _read_packet
    packet.raise_for_error()
  File "env/lib/python3.10/site-packages/pymysql/protocol.py", line 221, in raise_for_error
    err.raise_mysql_exception(self._data)
  File "env/lib/python3.10/site-packages/pymysql/err.py", line 143, in raise_mysql_exception
    raise errorclass(errno, errval)
pymysql.err.OperationalError: (1045, "Access denied for user '_2117e1e8e8ec4e5b'@'localhost' (using password: YES)")

Backup failed for Site test.com. Database or site_config.json may be corrupted
Traceback (most recent call last):
  File "apps/frappe/frappe/commands/site.py", line 718, in backup
    odb = scheduled_backup(
  File "apps/frappe/frappe/utils/backups.py", line 532, in scheduled_backup
    odb = new_backup(
  File "apps/frappe/frappe/utils/backups.py", line 566, in new_backup
    odb = BackupGenerator(
  File "apps/frappe/frappe/utils/backups.py", line 84, in __init__
    self.setup_backup_tables()
  File "apps/frappe/frappe/utils/backups.py", line 116, in setup_backup_tables
    existing_tables = frappe.db.get_tables()
  File "apps/frappe/frappe/database/mariadb/database.py", line 425, in get_tables
    frappe.qb.from_(information_schema.tables)
  File "apps/frappe/frappe/query_builder/utils.py", line 76, in execute_query
    return frappe.db.sql(query, params, *args, **kwargs)  # nosemgrep
  File "apps/frappe/frappe/database/database.py", line 201, in sql
    self.connect()
  File "apps/frappe/frappe/database/database.py", line 115, in connect
    self._conn = self.get_connection()
  File "apps/frappe/frappe/database/mariadb/database.py", line 98, in get_connection
    conn = self._get_connection()
  File "apps/frappe/frappe/database/mariadb/database.py", line 104, in _get_connection
    return self.create_connection()
  File "apps/frappe/frappe/database/mariadb/database.py", line 107, in create_connection
    return pymysql.connect(**self.get_connection_settings())
  File "env/lib/python3.10/site-packages/pymysql/connections.py", line 352, in __init__
    self.connect()
  File "env/lib/python3.10/site-packages/pymysql/connections.py", line 636, in connect
    self._request_authentication()
  File "env/lib/python3.10/site-packages/pymysql/connections.py", line 911, in _request_authentication
    auth_packet = self._read_packet()
  File "env/lib/python3.10/site-packages/pymysql/connections.py", line 729, in _read_packet
    packet.raise_for_error()
  File "env/lib/python3.10/site-packages/pymysql/protocol.py", line 221, in raise_for_error
    err.raise_mysql_exception(self._data)
  File "env/lib/python3.10/site-packages/pymysql/err.py", line 143, in raise_mysql_exception
    raise errorclass(errno, errval)
pymysql.err.OperationalError: (1045, "Access denied for user '_2117e1e8e8ec4e5b'@'localhost' (using password: YES)")

Backup failed for Site test.in. Database or site_config.json may be corrupted
Traceback (most recent call last):
  File "apps/frappe/frappe/commands/site.py", line 718, in backup
    odb = scheduled_backup(
  File "apps/frappe/frappe/utils/backups.py", line 532, in scheduled_backup
    odb = new_backup(
  File "apps/frappe/frappe/utils/backups.py", line 566, in new_backup
    odb = BackupGenerator(
  File "apps/frappe/frappe/utils/backups.py", line 84, in __init__
    self.setup_backup_tables()
  File "apps/frappe/frappe/utils/backups.py", line 116, in setup_backup_tables
    existing_tables = frappe.db.get_tables()
  File "apps/frappe/frappe/database/mariadb/database.py", line 425, in get_tables
    frappe.qb.from_(information_schema.tables)
  File "apps/frappe/frappe/query_builder/utils.py", line 76, in execute_query
    return frappe.db.sql(query, params, *args, **kwargs)  # nosemgrep
  File "apps/frappe/frappe/database/database.py", line 201, in sql
    self.connect()
  File "apps/frappe/frappe/database/database.py", line 115, in connect
    self._conn = self.get_connection()
  File "apps/frappe/frappe/database/mariadb/database.py", line 98, in get_connection
    conn = self._get_connection()
  File "apps/frappe/frappe/database/mariadb/database.py", line 104, in _get_connection
    return self.create_connection()
  File "apps/frappe/frappe/database/mariadb/database.py", line 107, in create_connection
    return pymysql.connect(**self.get_connection_settings())
  File "env/lib/python3.10/site-packages/pymysql/connections.py", line 352, in __init__
    self.connect()
  File "env/lib/python3.10/site-packages/pymysql/connections.py", line 636, in connect
    self._request_authentication()
  File "env/lib/python3.10/site-packages/pymysql/connections.py", line 911, in _request_authentication
    auth_packet = self._read_packet()
  File "env/lib/python3.10/site-packages/pymysql/connections.py", line 729, in _read_packet
    packet.raise_for_error()
  File "env/lib/python3.10/site-packages/pymysql/protocol.py", line 221, in raise_for_error
    err.raise_mysql_exception(self._data)
  File "env/lib/python3.10/site-packages/pymysql/err.py", line 143, in raise_mysql_exception
    raise errorclass(errno, errval)
pymysql.err.OperationalError: (1045, "Access denied for user '_2117e1e8e8ec4e5b'@'localhost' (using password: YES)")

self=$$;  ( mysqldump --single-transaction --quick --lock-tables=false -u _5a217055bf43ac19 -p********** _5a217055bf43ac19 -h 127.0.0.1 -P 3306   || kill $self )  | /usr/bin/gzip >> ./india.in/private/backups/20230904_120002-india_in-database.sql.gz

Backup Summary for india.in at 2023-09-04 12:00:03.900319
Config  : ./india.in/private/backups/20230904_120002-india_in-site_config_backup.json 94.0B
Database: ./india.in/private/backups/20230904_120002-india_in-database.sql.gz         1.2MiB
Backup for Site india.in has been successfully completed
Backup failed for Site library.test. Database or site_config.json may be corrupted
Traceback (most recent call last):
  File "apps/frappe/frappe/commands/site.py", line 718, in backup
    odb = scheduled_backup(
  File "apps/frappe/frappe/utils/backups.py", line 532, in scheduled_backup
    odb = new_backup(
  File "apps/frappe/frappe/utils/backups.py", line 566, in new_backup
    odb = BackupGenerator(
  File "apps/frappe/frappe/utils/backups.py", line 84, in __init__
    self.setup_backup_tables()
  File "apps/frappe/frappe/utils/backups.py", line 116, in setup_backup_tables
    existing_tables = frappe.db.get_tables()
  File "apps/frappe/frappe/database/mariadb/database.py", line 425, in get_tables
    frappe.qb.from_(information_schema.tables)
  File "apps/frappe/frappe/query_builder/utils.py", line 76, in execute_query
    return frappe.db.sql(query, params, *args, **kwargs)  # nosemgrep
  File "apps/frappe/frappe/database/database.py", line 201, in sql
    self.connect()
  File "apps/frappe/frappe/database/database.py", line 115, in connect
    self._conn = self.get_connection()
  File "apps/frappe/frappe/database/mariadb/database.py", line 98, in get_connection
    conn = self._get_connection()
  File "apps/frappe/frappe/database/mariadb/database.py", line 104, in _get_connection
    return self.create_connection()
  File "apps/frappe/frappe/database/mariadb/database.py", line 107, in create_connection
    return pymysql.connect(**self.get_connection_settings())
  File "env/lib/python3.10/site-packages/pymysql/connections.py", line 352, in __init__
    self.connect()
  File "env/lib/python3.10/site-packages/pymysql/connections.py", line 636, in connect
    self._request_authentication()
  File "env/lib/python3.10/site-packages/pymysql/connections.py", line 911, in _request_authentication
    auth_packet = self._read_packet()
  File "env/lib/python3.10/site-packages/pymysql/connections.py", line 729, in _read_packet
    packet.raise_for_error()
  File "env/lib/python3.10/site-packages/pymysql/protocol.py", line 221, in raise_for_error
    err.raise_mysql_exception(self._data)
  File "env/lib/python3.10/site-packages/pymysql/err.py", line 143, in raise_mysql_exception
    raise errorclass(errno, errval)
pymysql.err.OperationalError: (1045, "Access denied for user '_2117e1e8e8ec4e5b'@'localhost' (using password: YES)")

Backup failed for Site test.com. Database or site_config.json may be corrupted
Traceback (most recent call last):
  File "apps/frappe/frappe/commands/site.py", line 718, in backup
    odb = scheduled_backup(
  File "apps/frappe/frappe/utils/backups.py", line 532, in scheduled_backup
    odb = new_backup(
  File "apps/frappe/frappe/utils/backups.py", line 566, in new_backup
    odb = BackupGenerator(
  File "apps/frappe/frappe/utils/backups.py", line 84, in __init__
    self.setup_backup_tables()
  File "apps/frappe/frappe/utils/backups.py", line 116, in setup_backup_tables
    existing_tables = frappe.db.get_tables()
  File "apps/frappe/frappe/database/mariadb/database.py", line 425, in get_tables
    frappe.qb.from_(information_schema.tables)
  File "apps/frappe/frappe/query_builder/utils.py", line 76, in execute_query
    return frappe.db.sql(query, params, *args, **kwargs)  # nosemgrep
  File "apps/frappe/frappe/database/database.py", line 201, in sql
    self.connect()
  File "apps/frappe/frappe/database/database.py", line 115, in connect
    self._conn = self.get_connection()
  File "apps/frappe/frappe/database/mariadb/database.py", line 98, in get_connection
    conn = self._get_connection()
  File "apps/frappe/frappe/database/mariadb/database.py", line 104, in _get_connection
    return self.create_connection()
  File "apps/frappe/frappe/database/mariadb/database.py", line 107, in create_connection
    return pymysql.connect(**self.get_connection_settings())
  File "env/lib/python3.10/site-packages/pymysql/connections.py", line 352, in __init__
    self.connect()
  File "env/lib/python3.10/site-packages/pymysql/connections.py", line 636, in connect
    self._request_authentication()
  File "env/lib/python3.10/site-packages/pymysql/connections.py", line 911, in _request_authentication
    auth_packet = self._read_packet()
  File "env/lib/python3.10/site-packages/pymysql/connections.py", line 729, in _read_packet
    packet.raise_for_error()
  File "env/lib/python3.10/site-packages/pymysql/protocol.py", line 221, in raise_for_error
    err.raise_mysql_exception(self._data)
  File "env/lib/python3.10/site-packages/pymysql/err.py", line 143, in raise_mysql_exception
    raise errorclass(errno, errval)
pymysql.err.OperationalError: (1045, "Access denied for user '_2117e1e8e8ec4e5b'@'localhost' (using password: YES)")

Backup failed for Site test.in. Database or site_config.json may be corrupted
Traceback (most recent call last):
  File "apps/frappe/frappe/commands/site.py", line 718, in backup
    odb = scheduled_backup(
  File "apps/frappe/frappe/utils/backups.py", line 532, in scheduled_backup
    odb = new_backup(
  File "apps/frappe/frappe/utils/backups.py", line 566, in new_backup
    odb = BackupGenerator(
  File "apps/frappe/frappe/utils/backups.py", line 84, in __init__
    self.setup_backup_tables()
  File "apps/frappe/frappe/utils/backups.py", line 116, in setup_backup_tables
    existing_tables = frappe.db.get_tables()
  File "apps/frappe/frappe/database/mariadb/database.py", line 425, in get_tables
    frappe.qb.from_(information_schema.tables)
  File "apps/frappe/frappe/query_builder/utils.py", line 76, in execute_query
    return frappe.db.sql(query, params, *args, **kwargs)  # nosemgrep
  File "apps/frappe/frappe/database/database.py", line 201, in sql
    self.connect()
  File "apps/frappe/frappe/database/database.py", line 115, in connect
    self._conn = self.get_connection()
  File "apps/frappe/frappe/database/mariadb/database.py", line 98, in get_connection
    conn = self._get_connection()
  File "apps/frappe/frappe/database/mariadb/database.py", line 104, in _get_connection
    return self.create_connection()
  File "apps/frappe/frappe/database/mariadb/database.py", line 107, in create_connection
    return pymysql.connect(**self.get_connection_settings())
  File "env/lib/python3.10/site-packages/pymysql/connections.py", line 352, in __init__
    self.connect()
  File "env/lib/python3.10/site-packages/pymysql/connections.py", line 636, in connect
    self._request_authentication()
  File "env/lib/python3.10/site-packages/pymysql/connections.py", line 911, in _request_authentication
    auth_packet = self._read_packet()
  File "env/lib/python3.10/site-packages/pymysql/connections.py", line 729, in _read_packet
    packet.raise_for_error()
  File "env/lib/python3.10/site-packages/pymysql/protocol.py", line 221, in raise_for_error
    err.raise_mysql_exception(self._data)
  File "env/lib/python3.10/site-packages/pymysql/err.py", line 143, in raise_mysql_exception
    raise errorclass(errno, errval)
pymysql.err.OperationalError: (1045, "Access denied for user '_2117e1e8e8ec4e5b'@'localhost' (using password: YES)")

self=$$;  ( mysqldump --single-transaction --quick --lock-tables=false -u _5a217055bf43ac19 -p********** _5a217055bf43ac19 -h 127.0.0.1 -P 3306   || kill $self )  | /usr/bin/gzip >> ./india.in/private/backups/20230906_120002-india_in-database.sql.gz

Backup Summary for india.in at 2023-09-06 12:00:05.183534
Config  : ./india.in/private/backups/20230906_120002-india_in-site_config_backup.json 94.0B
Database: ./india.in/private/backups/20230906_120002-india_in-database.sql.gz         1.2MiB
Backup for Site india.in has been successfully completed
Backup failed for Site library.test. Database or site_config.json may be corrupted
Traceback (most recent call last):
  File "apps/frappe/frappe/commands/site.py", line 718, in backup
    odb = scheduled_backup(
  File "apps/frappe/frappe/utils/backups.py", line 532, in scheduled_backup
    odb = new_backup(
  File "apps/frappe/frappe/utils/backups.py", line 566, in new_backup
    odb = BackupGenerator(
  File "apps/frappe/frappe/utils/backups.py", line 84, in __init__
    self.setup_backup_tables()
  File "apps/frappe/frappe/utils/backups.py", line 116, in setup_backup_tables
    existing_tables = frappe.db.get_tables()
  File "apps/frappe/frappe/database/mariadb/database.py", line 425, in get_tables
    frappe.qb.from_(information_schema.tables)
  File "apps/frappe/frappe/query_builder/utils.py", line 76, in execute_query
    return frappe.db.sql(query, params, *args, **kwargs)  # nosemgrep
  File "apps/frappe/frappe/database/database.py", line 201, in sql
    self.connect()
  File "apps/frappe/frappe/database/database.py", line 115, in connect
    self._conn = self.get_connection()
  File "apps/frappe/frappe/database/mariadb/database.py", line 98, in get_connection
    conn = self._get_connection()
  File "apps/frappe/frappe/database/mariadb/database.py", line 104, in _get_connection
    return self.create_connection()
  File "apps/frappe/frappe/database/mariadb/database.py", line 107, in create_connection
    return pymysql.connect(**self.get_connection_settings())
  File "env/lib/python3.10/site-packages/pymysql/connections.py", line 352, in __init__
    self.connect()
  File "env/lib/python3.10/site-packages/pymysql/connections.py", line 636, in connect
    self._request_authentication()
  File "env/lib/python3.10/site-packages/pymysql/connections.py", line 911, in _request_authentication
    auth_packet = self._read_packet()
  File "env/lib/python3.10/site-packages/pymysql/connections.py", line 729, in _read_packet
    packet.raise_for_error()
  File "env/lib/python3.10/site-packages/pymysql/protocol.py", line 221, in raise_for_error
    err.raise_mysql_exception(self._data)
  File "env/lib/python3.10/site-packages/pymysql/err.py", line 143, in raise_mysql_exception
    raise errorclass(errno, errval)
pymysql.err.OperationalError: (1045, "Access denied for user '_2117e1e8e8ec4e5b'@'localhost' (using password: YES)")

Backup failed for Site test.com. Database or site_config.json may be corrupted
Traceback (most recent call last):
  File "apps/frappe/frappe/commands/site.py", line 718, in backup
    odb = scheduled_backup(
  File "apps/frappe/frappe/utils/backups.py", line 532, in scheduled_backup
    odb = new_backup(
  File "apps/frappe/frappe/utils/backups.py", line 566, in new_backup
    odb = BackupGenerator(
  File "apps/frappe/frappe/utils/backups.py", line 84, in __init__
    self.setup_backup_tables()
  File "apps/frappe/frappe/utils/backups.py", line 116, in setup_backup_tables
    existing_tables = frappe.db.get_tables()
  File "apps/frappe/frappe/database/mariadb/database.py", line 425, in get_tables
    frappe.qb.from_(information_schema.tables)
  File "apps/frappe/frappe/query_builder/utils.py", line 76, in execute_query
    return frappe.db.sql(query, params, *args, **kwargs)  # nosemgrep
  File "apps/frappe/frappe/database/database.py", line 201, in sql
    self.connect()
  File "apps/frappe/frappe/database/database.py", line 115, in connect
    self._conn = self.get_connection()
  File "apps/frappe/frappe/database/mariadb/database.py", line 98, in get_connection
    conn = self._get_connection()
  File "apps/frappe/frappe/database/mariadb/database.py", line 104, in _get_connection
    return self.create_connection()
  File "apps/frappe/frappe/database/mariadb/database.py", line 107, in create_connection
    return pymysql.connect(**self.get_connection_settings())
  File "env/lib/python3.10/site-packages/pymysql/connections.py", line 352, in __init__
    self.connect()
  File "env/lib/python3.10/site-packages/pymysql/connections.py", line 636, in connect
    self._request_authentication()
  File "env/lib/python3.10/site-packages/pymysql/connections.py", line 911, in _request_authentication
    auth_packet = self._read_packet()
  File "env/lib/python3.10/site-packages/pymysql/connections.py", line 729, in _read_packet
    packet.raise_for_error()
  File "env/lib/python3.10/site-packages/pymysql/protocol.py", line 221, in raise_for_error
    err.raise_mysql_exception(self._data)
  File "env/lib/python3.10/site-packages/pymysql/err.py", line 143, in raise_mysql_exception
    raise errorclass(errno, errval)
pymysql.err.OperationalError: (1045, "Access denied for user '_2117e1e8e8ec4e5b'@'localhost' (using password: YES)")

Backup failed for Site test.in. Database or site_config.json may be corrupted
Traceback (most recent call last):
  File "apps/frappe/frappe/commands/site.py", line 718, in backup
    odb = scheduled_backup(
  File "apps/frappe/frappe/utils/backups.py", line 532, in scheduled_backup
    odb = new_backup(
  File "apps/frappe/frappe/utils/backups.py", line 566, in new_backup
    odb = BackupGenerator(
  File "apps/frappe/frappe/utils/backups.py", line 84, in __init__
    self.setup_backup_tables()
  File "apps/frappe/frappe/utils/backups.py", line 116, in setup_backup_tables
    existing_tables = frappe.db.get_tables()
  File "apps/frappe/frappe/database/mariadb/database.py", line 425, in get_tables
    frappe.qb.from_(information_schema.tables)
  File "apps/frappe/frappe/query_builder/utils.py", line 76, in execute_query
    return frappe.db.sql(query, params, *args, **kwargs)  # nosemgrep
  File "apps/frappe/frappe/database/database.py", line 201, in sql
    self.connect()
  File "apps/frappe/frappe/database/database.py", line 115, in connect
    self._conn = self.get_connection()
  File "apps/frappe/frappe/database/mariadb/database.py", line 98, in get_connection
    conn = self._get_connection()
  File "apps/frappe/frappe/database/mariadb/database.py", line 104, in _get_connection
    return self.create_connection()
  File "apps/frappe/frappe/database/mariadb/database.py", line 107, in create_connection
    return pymysql.connect(**self.get_connection_settings())
  File "env/lib/python3.10/site-packages/pymysql/connections.py", line 352, in __init__
    self.connect()
  File "env/lib/python3.10/site-packages/pymysql/connections.py", line 636, in connect
    self._request_authentication()
  File "env/lib/python3.10/site-packages/pymysql/connections.py", line 911, in _request_authentication
    auth_packet = self._read_packet()
  File "env/lib/python3.10/site-packages/pymysql/connections.py", line 729, in _read_packet
    packet.raise_for_error()
  File "env/lib/python3.10/site-packages/pymysql/protocol.py", line 221, in raise_for_error
    err.raise_mysql_exception(self._data)
  File "env/lib/python3.10/site-packages/pymysql/err.py", line 143, in raise_mysql_exception
    raise errorclass(errno, errval)
pymysql.err.OperationalError: (1045, "Access denied for user '_2117e1e8e8ec4e5b'@'localhost' (using password: YES)")

self=$$;  ( mysqldump --single-transaction --quick --lock-tables=false -u _5a217055bf43ac19 -p********** _5a217055bf43ac19 -h 127.0.0.1 -P 3306   || kill $self )  | /usr/bin/gzip >> ./india.in/private/backups/20230907_120001-india_in-database.sql.gz

Backup Summary for india.in at 2023-09-07 12:00:02.867319
Config  : ./india.in/private/backups/20230907_120001-india_in-site_config_backup.json 94.0B
Database: ./india.in/private/backups/20230907_120001-india_in-database.sql.gz         1.2MiB
Backup for Site india.in has been successfully completed
Backup failed for Site library.test. Database or site_config.json may be corrupted
Traceback (most recent call last):
  File "apps/frappe/frappe/commands/site.py", line 718, in backup
    odb = scheduled_backup(
  File "apps/frappe/frappe/utils/backups.py", line 532, in scheduled_backup
    odb = new_backup(
  File "apps/frappe/frappe/utils/backups.py", line 566, in new_backup
    odb = BackupGenerator(
  File "apps/frappe/frappe/utils/backups.py", line 84, in __init__
    self.setup_backup_tables()
  File "apps/frappe/frappe/utils/backups.py", line 116, in setup_backup_tables
    existing_tables = frappe.db.get_tables()
  File "apps/frappe/frappe/database/mariadb/database.py", line 425, in get_tables
    frappe.qb.from_(information_schema.tables)
  File "apps/frappe/frappe/query_builder/utils.py", line 76, in execute_query
    return frappe.db.sql(query, params, *args, **kwargs)  # nosemgrep
  File "apps/frappe/frappe/database/database.py", line 201, in sql
    self.connect()
  File "apps/frappe/frappe/database/database.py", line 115, in connect
    self._conn = self.get_connection()
  File "apps/frappe/frappe/database/mariadb/database.py", line 98, in get_connection
    conn = self._get_connection()
  File "apps/frappe/frappe/database/mariadb/database.py", line 104, in _get_connection
    return self.create_connection()
  File "apps/frappe/frappe/database/mariadb/database.py", line 107, in create_connection
    return pymysql.connect(**self.get_connection_settings())
  File "env/lib/python3.10/site-packages/pymysql/connections.py", line 352, in __init__
    self.connect()
  File "env/lib/python3.10/site-packages/pymysql/connections.py", line 636, in connect
    self._request_authentication()
  File "env/lib/python3.10/site-packages/pymysql/connections.py", line 911, in _request_authentication
    auth_packet = self._read_packet()
  File "env/lib/python3.10/site-packages/pymysql/connections.py", line 729, in _read_packet
    packet.raise_for_error()
  File "env/lib/python3.10/site-packages/pymysql/protocol.py", line 221, in raise_for_error
    err.raise_mysql_exception(self._data)
  File "env/lib/python3.10/site-packages/pymysql/err.py", line 143, in raise_mysql_exception
    raise errorclass(errno, errval)
pymysql.err.OperationalError: (1045, "Access denied for user '_2117e1e8e8ec4e5b'@'localhost' (using password: YES)")

Backup failed for Site test.com. Database or site_config.json may be corrupted
Traceback (most recent call last):
  File "apps/frappe/frappe/commands/site.py", line 718, in backup
    odb = scheduled_backup(
  File "apps/frappe/frappe/utils/backups.py", line 532, in scheduled_backup
    odb = new_backup(
  File "apps/frappe/frappe/utils/backups.py", line 566, in new_backup
    odb = BackupGenerator(
  File "apps/frappe/frappe/utils/backups.py", line 84, in __init__
    self.setup_backup_tables()
  File "apps/frappe/frappe/utils/backups.py", line 116, in setup_backup_tables
    existing_tables = frappe.db.get_tables()
  File "apps/frappe/frappe/database/mariadb/database.py", line 425, in get_tables
    frappe.qb.from_(information_schema.tables)
  File "apps/frappe/frappe/query_builder/utils.py", line 76, in execute_query
    return frappe.db.sql(query, params, *args, **kwargs)  # nosemgrep
  File "apps/frappe/frappe/database/database.py", line 201, in sql
    self.connect()
  File "apps/frappe/frappe/database/database.py", line 115, in connect
    self._conn = self.get_connection()
  File "apps/frappe/frappe/database/mariadb/database.py", line 98, in get_connection
    conn = self._get_connection()
  File "apps/frappe/frappe/database/mariadb/database.py", line 104, in _get_connection
    return self.create_connection()
  File "apps/frappe/frappe/database/mariadb/database.py", line 107, in create_connection
    return pymysql.connect(**self.get_connection_settings())
  File "env/lib/python3.10/site-packages/pymysql/connections.py", line 352, in __init__
    self.connect()
  File "env/lib/python3.10/site-packages/pymysql/connections.py", line 636, in connect
    self._request_authentication()
  File "env/lib/python3.10/site-packages/pymysql/connections.py", line 911, in _request_authentication
    auth_packet = self._read_packet()
  File "env/lib/python3.10/site-packages/pymysql/connections.py", line 729, in _read_packet
    packet.raise_for_error()
  File "env/lib/python3.10/site-packages/pymysql/protocol.py", line 221, in raise_for_error
    err.raise_mysql_exception(self._data)
  File "env/lib/python3.10/site-packages/pymysql/err.py", line 143, in raise_mysql_exception
    raise errorclass(errno, errval)
pymysql.err.OperationalError: (1045, "Access denied for user '_2117e1e8e8ec4e5b'@'localhost' (using password: YES)")

Backup failed for Site test.in. Database or site_config.json may be corrupted
Traceback (most recent call last):
  File "apps/frappe/frappe/commands/site.py", line 718, in backup
    odb = scheduled_backup(
  File "apps/frappe/frappe/utils/backups.py", line 532, in scheduled_backup
    odb = new_backup(
  File "apps/frappe/frappe/utils/backups.py", line 566, in new_backup
    odb = BackupGenerator(
  File "apps/frappe/frappe/utils/backups.py", line 84, in __init__
    self.setup_backup_tables()
  File "apps/frappe/frappe/utils/backups.py", line 116, in setup_backup_tables
    existing_tables = frappe.db.get_tables()
  File "apps/frappe/frappe/database/mariadb/database.py", line 425, in get_tables
    frappe.qb.from_(information_schema.tables)
  File "apps/frappe/frappe/query_builder/utils.py", line 76, in execute_query
    return frappe.db.sql(query, params, *args, **kwargs)  # nosemgrep
  File "apps/frappe/frappe/database/database.py", line 201, in sql
    self.connect()
  File "apps/frappe/frappe/database/database.py", line 115, in connect
    self._conn = self.get_connection()
  File "apps/frappe/frappe/database/mariadb/database.py", line 98, in get_connection
    conn = self._get_connection()
  File "apps/frappe/frappe/database/mariadb/database.py", line 104, in _get_connection
    return self.create_connection()
  File "apps/frappe/frappe/database/mariadb/database.py", line 107, in create_connection
    return pymysql.connect(**self.get_connection_settings())
  File "env/lib/python3.10/site-packages/pymysql/connections.py", line 352, in __init__
    self.connect()
  File "env/lib/python3.10/site-packages/pymysql/connections.py", line 636, in connect
    self._request_authentication()
  File "env/lib/python3.10/site-packages/pymysql/connections.py", line 911, in _request_authentication
    auth_packet = self._read_packet()
  File "env/lib/python3.10/site-packages/pymysql/connections.py", line 729, in _read_packet
    packet.raise_for_error()
  File "env/lib/python3.10/site-packages/pymysql/protocol.py", line 221, in raise_for_error
    err.raise_mysql_exception(self._data)
  File "env/lib/python3.10/site-packages/pymysql/err.py", line 143, in raise_mysql_exception
    raise errorclass(errno, errval)
pymysql.err.OperationalError: (1045, "Access denied for user '_2117e1e8e8ec4e5b'@'localhost' (using password: YES)")

self=$$;  ( mysqldump --single-transaction --quick --lock-tables=false -u _5a217055bf43ac19 -p********** _5a217055bf43ac19 -h 127.0.0.1 -P 3306   || kill $self )  | /usr/bin/gzip >> ./india.in/private/backups/20230912_120002-india_in-database.sql.gz

Backup Summary for india.in at 2023-09-12 12:00:03.501415
Config  : ./india.in/private/backups/20230912_120002-india_in-site_config_backup.json 94.0B
Database: ./india.in/private/backups/20230912_120002-india_in-database.sql.gz         1.1MiB
Backup for Site india.in has been successfully completed
Backup failed for Site library.test. Database or site_config.json may be corrupted
Traceback (most recent call last):
  File "apps/frappe/frappe/commands/site.py", line 718, in backup
    odb = scheduled_backup(
  File "apps/frappe/frappe/utils/backups.py", line 532, in scheduled_backup
    odb = new_backup(
  File "apps/frappe/frappe/utils/backups.py", line 566, in new_backup
    odb = BackupGenerator(
  File "apps/frappe/frappe/utils/backups.py", line 84, in __init__
    self.setup_backup_tables()
  File "apps/frappe/frappe/utils/backups.py", line 116, in setup_backup_tables
    existing_tables = frappe.db.get_tables()
  File "apps/frappe/frappe/database/mariadb/database.py", line 425, in get_tables
    frappe.qb.from_(information_schema.tables)
  File "apps/frappe/frappe/query_builder/utils.py", line 76, in execute_query
    return frappe.db.sql(query, params, *args, **kwargs)  # nosemgrep
  File "apps/frappe/frappe/database/database.py", line 201, in sql
    self.connect()
  File "apps/frappe/frappe/database/database.py", line 115, in connect
    self._conn = self.get_connection()
  File "apps/frappe/frappe/database/mariadb/database.py", line 98, in get_connection
    conn = self._get_connection()
  File "apps/frappe/frappe/database/mariadb/database.py", line 104, in _get_connection
    return self.create_connection()
  File "apps/frappe/frappe/database/mariadb/database.py", line 107, in create_connection
    return pymysql.connect(**self.get_connection_settings())
  File "env/lib/python3.10/site-packages/pymysql/connections.py", line 352, in __init__
    self.connect()
  File "env/lib/python3.10/site-packages/pymysql/connections.py", line 636, in connect
    self._request_authentication()
  File "env/lib/python3.10/site-packages/pymysql/connections.py", line 911, in _request_authentication
    auth_packet = self._read_packet()
  File "env/lib/python3.10/site-packages/pymysql/connections.py", line 729, in _read_packet
    packet.raise_for_error()
  File "env/lib/python3.10/site-packages/pymysql/protocol.py", line 221, in raise_for_error
    err.raise_mysql_exception(self._data)
  File "env/lib/python3.10/site-packages/pymysql/err.py", line 143, in raise_mysql_exception
    raise errorclass(errno, errval)
pymysql.err.OperationalError: (1045, "Access denied for user '_2117e1e8e8ec4e5b'@'localhost' (using password: YES)")

Backup failed for Site test.com. Database or site_config.json may be corrupted
Traceback (most recent call last):
  File "apps/frappe/frappe/commands/site.py", line 718, in backup
    odb = scheduled_backup(
  File "apps/frappe/frappe/utils/backups.py", line 532, in scheduled_backup
    odb = new_backup(
  File "apps/frappe/frappe/utils/backups.py", line 566, in new_backup
    odb = BackupGenerator(
  File "apps/frappe/frappe/utils/backups.py", line 84, in __init__
    self.setup_backup_tables()
  File "apps/frappe/frappe/utils/backups.py", line 116, in setup_backup_tables
    existing_tables = frappe.db.get_tables()
  File "apps/frappe/frappe/database/mariadb/database.py", line 425, in get_tables
    frappe.qb.from_(information_schema.tables)
  File "apps/frappe/frappe/query_builder/utils.py", line 76, in execute_query
    return frappe.db.sql(query, params, *args, **kwargs)  # nosemgrep
  File "apps/frappe/frappe/database/database.py", line 201, in sql
    self.connect()
  File "apps/frappe/frappe/database/database.py", line 115, in connect
    self._conn = self.get_connection()
  File "apps/frappe/frappe/database/mariadb/database.py", line 98, in get_connection
    conn = self._get_connection()
  File "apps/frappe/frappe/database/mariadb/database.py", line 104, in _get_connection
    return self.create_connection()
  File "apps/frappe/frappe/database/mariadb/database.py", line 107, in create_connection
    return pymysql.connect(**self.get_connection_settings())
  File "env/lib/python3.10/site-packages/pymysql/connections.py", line 352, in __init__
    self.connect()
  File "env/lib/python3.10/site-packages/pymysql/connections.py", line 636, in connect
    self._request_authentication()
  File "env/lib/python3.10/site-packages/pymysql/connections.py", line 911, in _request_authentication
    auth_packet = self._read_packet()
  File "env/lib/python3.10/site-packages/pymysql/connections.py", line 729, in _read_packet
    packet.raise_for_error()
  File "env/lib/python3.10/site-packages/pymysql/protocol.py", line 221, in raise_for_error
    err.raise_mysql_exception(self._data)
  File "env/lib/python3.10/site-packages/pymysql/err.py", line 143, in raise_mysql_exception
    raise errorclass(errno, errval)
pymysql.err.OperationalError: (1045, "Access denied for user '_2117e1e8e8ec4e5b'@'localhost' (using password: YES)")

Backup failed for Site test.in. Database or site_config.json may be corrupted
Traceback (most recent call last):
  File "apps/frappe/frappe/commands/site.py", line 718, in backup
    odb = scheduled_backup(
  File "apps/frappe/frappe/utils/backups.py", line 532, in scheduled_backup
    odb = new_backup(
  File "apps/frappe/frappe/utils/backups.py", line 566, in new_backup
    odb = BackupGenerator(
  File "apps/frappe/frappe/utils/backups.py", line 84, in __init__
    self.setup_backup_tables()
  File "apps/frappe/frappe/utils/backups.py", line 116, in setup_backup_tables
    existing_tables = frappe.db.get_tables()
  File "apps/frappe/frappe/database/mariadb/database.py", line 425, in get_tables
    frappe.qb.from_(information_schema.tables)
  File "apps/frappe/frappe/query_builder/utils.py", line 76, in execute_query
    return frappe.db.sql(query, params, *args, **kwargs)  # nosemgrep
  File "apps/frappe/frappe/database/database.py", line 201, in sql
    self.connect()
  File "apps/frappe/frappe/database/database.py", line 115, in connect
    self._conn = self.get_connection()
  File "apps/frappe/frappe/database/mariadb/database.py", line 98, in get_connection
    conn = self._get_connection()
  File "apps/frappe/frappe/database/mariadb/database.py", line 104, in _get_connection
    return self.create_connection()
  File "apps/frappe/frappe/database/mariadb/database.py", line 107, in create_connection
    return pymysql.connect(**self.get_connection_settings())
  File "env/lib/python3.10/site-packages/pymysql/connections.py", line 352, in __init__
    self.connect()
  File "env/lib/python3.10/site-packages/pymysql/connections.py", line 636, in connect
    self._request_authentication()
  File "env/lib/python3.10/site-packages/pymysql/connections.py", line 911, in _request_authentication
    auth_packet = self._read_packet()
  File "env/lib/python3.10/site-packages/pymysql/connections.py", line 729, in _read_packet
    packet.raise_for_error()
  File "env/lib/python3.10/site-packages/pymysql/protocol.py", line 221, in raise_for_error
    err.raise_mysql_exception(self._data)
  File "env/lib/python3.10/site-packages/pymysql/err.py", line 143, in raise_mysql_exception
    raise errorclass(errno, errval)
pymysql.err.OperationalError: (1045, "Access denied for user '_2117e1e8e8ec4e5b'@'localhost' (using password: YES)")

self=$$;  ( mysqldump --single-transaction --quick --lock-tables=false -u _5a217055bf43ac19 -p********** _5a217055bf43ac19 -h 127.0.0.1 -P 3306   || kill $self )  | /usr/bin/gzip >> ./india.in/private/backups/20230916_120001-india_in-database.sql.gz

Backup Summary for india.in at 2023-09-16 12:00:03.001971
Config  : ./india.in/private/backups/20230916_120001-india_in-site_config_backup.json 94.0B
Database: ./india.in/private/backups/20230916_120001-india_in-database.sql.gz         1.1MiB
Backup for Site india.in has been successfully completed
Backup failed for Site library.test. Database or site_config.json may be corrupted
Traceback (most recent call last):
  File "apps/frappe/frappe/commands/site.py", line 718, in backup
    odb = scheduled_backup(
  File "apps/frappe/frappe/utils/backups.py", line 532, in scheduled_backup
    odb = new_backup(
  File "apps/frappe/frappe/utils/backups.py", line 566, in new_backup
    odb = BackupGenerator(
  File "apps/frappe/frappe/utils/backups.py", line 84, in __init__
    self.setup_backup_tables()
  File "apps/frappe/frappe/utils/backups.py", line 116, in setup_backup_tables
    existing_tables = frappe.db.get_tables()
  File "apps/frappe/frappe/database/mariadb/database.py", line 425, in get_tables
    frappe.qb.from_(information_schema.tables)
  File "apps/frappe/frappe/query_builder/utils.py", line 76, in execute_query
    return frappe.db.sql(query, params, *args, **kwargs)  # nosemgrep
  File "apps/frappe/frappe/database/database.py", line 201, in sql
    self.connect()
  File "apps/frappe/frappe/database/database.py", line 115, in connect
    self._conn = self.get_connection()
  File "apps/frappe/frappe/database/mariadb/database.py", line 98, in get_connection
    conn = self._get_connection()
  File "apps/frappe/frappe/database/mariadb/database.py", line 104, in _get_connection
    return self.create_connection()
  File "apps/frappe/frappe/database/mariadb/database.py", line 107, in create_connection
    return pymysql.connect(**self.get_connection_settings())
  File "env/lib/python3.10/site-packages/pymysql/connections.py", line 352, in __init__
    self.connect()
  File "env/lib/python3.10/site-packages/pymysql/connections.py", line 636, in connect
    self._request_authentication()
  File "env/lib/python3.10/site-packages/pymysql/connections.py", line 911, in _request_authentication
    auth_packet = self._read_packet()
  File "env/lib/python3.10/site-packages/pymysql/connections.py", line 729, in _read_packet
    packet.raise_for_error()
  File "env/lib/python3.10/site-packages/pymysql/protocol.py", line 221, in raise_for_error
    err.raise_mysql_exception(self._data)
  File "env/lib/python3.10/site-packages/pymysql/err.py", line 143, in raise_mysql_exception
    raise errorclass(errno, errval)
pymysql.err.OperationalError: (1045, "Access denied for user '_2117e1e8e8ec4e5b'@'localhost' (using password: YES)")

Backup failed for Site test.com. Database or site_config.json may be corrupted
Traceback (most recent call last):
  File "apps/frappe/frappe/commands/site.py", line 718, in backup
    odb = scheduled_backup(
  File "apps/frappe/frappe/utils/backups.py", line 532, in scheduled_backup
    odb = new_backup(
  File "apps/frappe/frappe/utils/backups.py", line 566, in new_backup
    odb = BackupGenerator(
  File "apps/frappe/frappe/utils/backups.py", line 84, in __init__
    self.setup_backup_tables()
  File "apps/frappe/frappe/utils/backups.py", line 116, in setup_backup_tables
    existing_tables = frappe.db.get_tables()
  File "apps/frappe/frappe/database/mariadb/database.py", line 425, in get_tables
    frappe.qb.from_(information_schema.tables)
  File "apps/frappe/frappe/query_builder/utils.py", line 76, in execute_query
    return frappe.db.sql(query, params, *args, **kwargs)  # nosemgrep
  File "apps/frappe/frappe/database/database.py", line 201, in sql
    self.connect()
  File "apps/frappe/frappe/database/database.py", line 115, in connect
    self._conn = self.get_connection()
  File "apps/frappe/frappe/database/mariadb/database.py", line 98, in get_connection
    conn = self._get_connection()
  File "apps/frappe/frappe/database/mariadb/database.py", line 104, in _get_connection
    return self.create_connection()
  File "apps/frappe/frappe/database/mariadb/database.py", line 107, in create_connection
    return pymysql.connect(**self.get_connection_settings())
  File "env/lib/python3.10/site-packages/pymysql/connections.py", line 352, in __init__
    self.connect()
  File "env/lib/python3.10/site-packages/pymysql/connections.py", line 636, in connect
    self._request_authentication()
  File "env/lib/python3.10/site-packages/pymysql/connections.py", line 911, in _request_authentication
    auth_packet = self._read_packet()
  File "env/lib/python3.10/site-packages/pymysql/connections.py", line 729, in _read_packet
    packet.raise_for_error()
  File "env/lib/python3.10/site-packages/pymysql/protocol.py", line 221, in raise_for_error
    err.raise_mysql_exception(self._data)
  File "env/lib/python3.10/site-packages/pymysql/err.py", line 143, in raise_mysql_exception
    raise errorclass(errno, errval)
pymysql.err.OperationalError: (1045, "Access denied for user '_2117e1e8e8ec4e5b'@'localhost' (using password: YES)")

Backup failed for Site test.in. Database or site_config.json may be corrupted
Traceback (most recent call last):
  File "apps/frappe/frappe/commands/site.py", line 718, in backup
    odb = scheduled_backup(
  File "apps/frappe/frappe/utils/backups.py", line 532, in scheduled_backup
    odb = new_backup(
  File "apps/frappe/frappe/utils/backups.py", line 566, in new_backup
    odb = BackupGenerator(
  File "apps/frappe/frappe/utils/backups.py", line 84, in __init__
    self.setup_backup_tables()
  File "apps/frappe/frappe/utils/backups.py", line 116, in setup_backup_tables
    existing_tables = frappe.db.get_tables()
  File "apps/frappe/frappe/database/mariadb/database.py", line 425, in get_tables
    frappe.qb.from_(information_schema.tables)
  File "apps/frappe/frappe/query_builder/utils.py", line 76, in execute_query
    return frappe.db.sql(query, params, *args, **kwargs)  # nosemgrep
  File "apps/frappe/frappe/database/database.py", line 201, in sql
    self.connect()
  File "apps/frappe/frappe/database/database.py", line 115, in connect
    self._conn = self.get_connection()
  File "apps/frappe/frappe/database/mariadb/database.py", line 98, in get_connection
    conn = self._get_connection()
  File "apps/frappe/frappe/database/mariadb/database.py", line 104, in _get_connection
    return self.create_connection()
  File "apps/frappe/frappe/database/mariadb/database.py", line 107, in create_connection
    return pymysql.connect(**self.get_connection_settings())
  File "env/lib/python3.10/site-packages/pymysql/connections.py", line 352, in __init__
    self.connect()
  File "env/lib/python3.10/site-packages/pymysql/connections.py", line 636, in connect
    self._request_authentication()
  File "env/lib/python3.10/site-packages/pymysql/connections.py", line 911, in _request_authentication
    auth_packet = self._read_packet()
  File "env/lib/python3.10/site-packages/pymysql/connections.py", line 729, in _read_packet
    packet.raise_for_error()
  File "env/lib/python3.10/site-packages/pymysql/protocol.py", line 221, in raise_for_error
    err.raise_mysql_exception(self._data)
  File "env/lib/python3.10/site-packages/pymysql/err.py", line 143, in raise_mysql_exception
    raise errorclass(errno, errval)
pymysql.err.OperationalError: (1045, "Access denied for user '_2117e1e8e8ec4e5b'@'localhost' (using password: YES)")

self=$$;  ( mysqldump --single-transaction --quick --lock-tables=false -u _5a217055bf43ac19 -p********** _5a217055bf43ac19 -h 127.0.0.1 -P 3306   || kill $self )  | /usr/bin/gzip >> ./india.in/private/backups/20230918_120002-india_in-database.sql.gz

Backup Summary for india.in at 2023-09-18 12:00:03.864076
Config  : ./india.in/private/backups/20230918_120002-india_in-site_config_backup.json 94.0B
Database: ./india.in/private/backups/20230918_120002-india_in-database.sql.gz         1.1MiB
Backup for Site india.in has been successfully completed
Backup failed for Site library.test. Database or site_config.json may be corrupted
Traceback (most recent call last):
  File "apps/frappe/frappe/commands/site.py", line 718, in backup
    odb = scheduled_backup(
  File "apps/frappe/frappe/utils/backups.py", line 532, in scheduled_backup
    odb = new_backup(
  File "apps/frappe/frappe/utils/backups.py", line 566, in new_backup
    odb = BackupGenerator(
  File "apps/frappe/frappe/utils/backups.py", line 84, in __init__
    self.setup_backup_tables()
  File "apps/frappe/frappe/utils/backups.py", line 116, in setup_backup_tables
    existing_tables = frappe.db.get_tables()
  File "apps/frappe/frappe/database/mariadb/database.py", line 425, in get_tables
    frappe.qb.from_(information_schema.tables)
  File "apps/frappe/frappe/query_builder/utils.py", line 76, in execute_query
    return frappe.db.sql(query, params, *args, **kwargs)  # nosemgrep
  File "apps/frappe/frappe/database/database.py", line 201, in sql
    self.connect()
  File "apps/frappe/frappe/database/database.py", line 115, in connect
    self._conn = self.get_connection()
  File "apps/frappe/frappe/database/mariadb/database.py", line 98, in get_connection
    conn = self._get_connection()
  File "apps/frappe/frappe/database/mariadb/database.py", line 104, in _get_connection
    return self.create_connection()
  File "apps/frappe/frappe/database/mariadb/database.py", line 107, in create_connection
    return pymysql.connect(**self.get_connection_settings())
  File "env/lib/python3.10/site-packages/pymysql/connections.py", line 352, in __init__
    self.connect()
  File "env/lib/python3.10/site-packages/pymysql/connections.py", line 636, in connect
    self._request_authentication()
  File "env/lib/python3.10/site-packages/pymysql/connections.py", line 911, in _request_authentication
    auth_packet = self._read_packet()
  File "env/lib/python3.10/site-packages/pymysql/connections.py", line 729, in _read_packet
    packet.raise_for_error()
  File "env/lib/python3.10/site-packages/pymysql/protocol.py", line 221, in raise_for_error
    err.raise_mysql_exception(self._data)
  File "env/lib/python3.10/site-packages/pymysql/err.py", line 143, in raise_mysql_exception
    raise errorclass(errno, errval)
pymysql.err.OperationalError: (1045, "Access denied for user '_2117e1e8e8ec4e5b'@'localhost' (using password: YES)")

Backup failed for Site test.com. Database or site_config.json may be corrupted
Traceback (most recent call last):
  File "apps/frappe/frappe/commands/site.py", line 718, in backup
    odb = scheduled_backup(
  File "apps/frappe/frappe/utils/backups.py", line 532, in scheduled_backup
    odb = new_backup(
  File "apps/frappe/frappe/utils/backups.py", line 566, in new_backup
    odb = BackupGenerator(
  File "apps/frappe/frappe/utils/backups.py", line 84, in __init__
    self.setup_backup_tables()
  File "apps/frappe/frappe/utils/backups.py", line 116, in setup_backup_tables
    existing_tables = frappe.db.get_tables()
  File "apps/frappe/frappe/database/mariadb/database.py", line 425, in get_tables
    frappe.qb.from_(information_schema.tables)
  File "apps/frappe/frappe/query_builder/utils.py", line 76, in execute_query
    return frappe.db.sql(query, params, *args, **kwargs)  # nosemgrep
  File "apps/frappe/frappe/database/database.py", line 201, in sql
    self.connect()
  File "apps/frappe/frappe/database/database.py", line 115, in connect
    self._conn = self.get_connection()
  File "apps/frappe/frappe/database/mariadb/database.py", line 98, in get_connection
    conn = self._get_connection()
  File "apps/frappe/frappe/database/mariadb/database.py", line 104, in _get_connection
    return self.create_connection()
  File "apps/frappe/frappe/database/mariadb/database.py", line 107, in create_connection
    return pymysql.connect(**self.get_connection_settings())
  File "env/lib/python3.10/site-packages/pymysql/connections.py", line 352, in __init__
    self.connect()
  File "env/lib/python3.10/site-packages/pymysql/connections.py", line 636, in connect
    self._request_authentication()
  File "env/lib/python3.10/site-packages/pymysql/connections.py", line 911, in _request_authentication
    auth_packet = self._read_packet()
  File "env/lib/python3.10/site-packages/pymysql/connections.py", line 729, in _read_packet
    packet.raise_for_error()
  File "env/lib/python3.10/site-packages/pymysql/protocol.py", line 221, in raise_for_error
    err.raise_mysql_exception(self._data)
  File "env/lib/python3.10/site-packages/pymysql/err.py", line 143, in raise_mysql_exception
    raise errorclass(errno, errval)
pymysql.err.OperationalError: (1045, "Access denied for user '_2117e1e8e8ec4e5b'@'localhost' (using password: YES)")

Backup failed for Site test.in. Database or site_config.json may be corrupted
Traceback (most recent call last):
  File "apps/frappe/frappe/commands/site.py", line 718, in backup
    odb = scheduled_backup(
  File "apps/frappe/frappe/utils/backups.py", line 532, in scheduled_backup
    odb = new_backup(
  File "apps/frappe/frappe/utils/backups.py", line 566, in new_backup
    odb = BackupGenerator(
  File "apps/frappe/frappe/utils/backups.py", line 84, in __init__
    self.setup_backup_tables()
  File "apps/frappe/frappe/utils/backups.py", line 116, in setup_backup_tables
    existing_tables = frappe.db.get_tables()
  File "apps/frappe/frappe/database/mariadb/database.py", line 425, in get_tables
    frappe.qb.from_(information_schema.tables)
  File "apps/frappe/frappe/query_builder/utils.py", line 76, in execute_query
    return frappe.db.sql(query, params, *args, **kwargs)  # nosemgrep
  File "apps/frappe/frappe/database/database.py", line 201, in sql
    self.connect()
  File "apps/frappe/frappe/database/database.py", line 115, in connect
    self._conn = self.get_connection()
  File "apps/frappe/frappe/database/mariadb/database.py", line 98, in get_connection
    conn = self._get_connection()
  File "apps/frappe/frappe/database/mariadb/database.py", line 104, in _get_connection
    return self.create_connection()
  File "apps/frappe/frappe/database/mariadb/database.py", line 107, in create_connection
    return pymysql.connect(**self.get_connection_settings())
  File "env/lib/python3.10/site-packages/pymysql/connections.py", line 352, in __init__
    self.connect()
  File "env/lib/python3.10/site-packages/pymysql/connections.py", line 636, in connect
    self._request_authentication()
  File "env/lib/python3.10/site-packages/pymysql/connections.py", line 911, in _request_authentication
    auth_packet = self._read_packet()
  File "env/lib/python3.10/site-packages/pymysql/connections.py", line 729, in _read_packet
    packet.raise_for_error()
  File "env/lib/python3.10/site-packages/pymysql/protocol.py", line 221, in raise_for_error
    err.raise_mysql_exception(self._data)
  File "env/lib/python3.10/site-packages/pymysql/err.py", line 143, in raise_mysql_exception
    raise errorclass(errno, errval)
pymysql.err.OperationalError: (1045, "Access denied for user '_2117e1e8e8ec4e5b'@'localhost' (using password: YES)")

