2023-08-16 22:48:32,123 ERROR scheduler Exception in Enqueue Events for Site india.in
Traceback (most recent call last):
  File "apps/frappe/frappe/utils/scheduler.py", line 73, in enqueue_events_for_site
    enqueue_events(site=site)
  File "apps/frappe/frappe/utils/scheduler.py", line 95, in enqueue_events
    frappe.get_doc("Scheduled Job Type", job_type.name).enqueue()
  File "apps/frappe/frappe/__init__.py", line 1196, in get_doc
    doc = frappe.model.document.get_doc(*args, **kwargs)
  File "apps/frappe/frappe/model/document.py", line 74, in get_doc
    return controller(*args, **kwargs)
  File "apps/frappe/frappe/model/document.py", line 106, in __init__
    self.load_from_db()
  File "apps/frappe/frappe/model/document.py", line 145, in load_from_db
    d = frappe.db.get_value(
  File "apps/frappe/frappe/database/database.py", line 509, in get_value
    result = self.get_values(
  File "apps/frappe/frappe/database/database.py", line 606, in get_values
    out = self._get_values_from_table(
  File "apps/frappe/frappe/database/database.py", line 836, in _get_values_from_table
    return query.run(as_dict=as_dict, debug=debug, update=update, run=run, pluck=pluck)
  File "apps/frappe/frappe/query_builder/utils.py", line 76, in execute_query
    return frappe.db.sql(query, params, *args, **kwargs)  # nosemgrep
  File "apps/frappe/frappe/database/database.py", line 220, in sql
    self._cursor.execute(query, values)
  File "env/lib/python3.10/site-packages/pymysql/cursors.py", line 158, in execute
    result = self._query(query)
  File "env/lib/python3.10/site-packages/pymysql/cursors.py", line 325, in _query
    conn.query(q)
  File "env/lib/python3.10/site-packages/pymysql/connections.py", line 549, in query
    self._affected_rows = self._read_query_result(unbuffered=unbuffered)
  File "env/lib/python3.10/site-packages/pymysql/connections.py", line 779, in _read_query_result
    result.read()
  File "env/lib/python3.10/site-packages/pymysql/connections.py", line 1157, in read
    first_packet = self.connection._read_packet()
  File "env/lib/python3.10/site-packages/pymysql/connections.py", line 696, in _read_packet
    packet_header = self._read_bytes(4)
  File "env/lib/python3.10/site-packages/pymysql/connections.py", line 752, in _read_bytes
    raise err.OperationalError(
pymysql.err.OperationalError: (2013, 'Lost connection to MySQL server during query')

